Workbook

Sheet Assumptions
A1: OpenBench — Assumptions Register (Team Inferno, Tech Zephyr Finale)
A2: Legend: blue = input you can change · black = formula · green = link to another sheet · yellow = key assumption. Change any blue cell; every sheet recalculates.
A4: ID | B4: Parameter | C4: Base | D4: Downside | E4: Upside | F4: Downside + response | G4: Unit | H4: Source / rationale
A5: A1 | B5: Capture of Exhibit 2 mature volume | C5: 0.85 | D5: 0.65 | E5: 1 | F5: =D5 -> 0.65 | G5: % | H5: Pilot runs at 17.5 vs 20 baseline bookings/host = 87.5% (Ex.1, Ex.3). Base 85%; downside 65%.
A6: A2 | B6: Ramp: share of mature volume, live month 1 | C6: 0.3 | D6: =C6 -> 0.3 | E6: =C6 -> 0.3 | F6: =D6 -> 0.3 | G6: % | H6: Team assumption: new host needs ~3 months to fill committed slots
A7: A3 | B7: Ramp: live month 2 | C7: 0.6 | D7: =C7 -> 0.6 | E7: =C7 -> 0.6 | F7: =D7 -> 0.6 | G7: % | H7: Team assumption
A8: A4 | B8: Ramp: live month 3 | C8: 0.85 | D8: =C8 -> 0.85 | E8: =C8 -> 0.85 | F8: =D8 -> 0.85 | G8: % | H8: Team assumption
A9: A5 | B9: Ramp: live month 4+ | C9: 1 | D9: =C9 -> 1 | E9: =C9 -> 1 | F9: =D9 -> 1 | G9: % | H9: Team assumption
A10: A6 | B10: Pilot host bookings/month today | C10: 17.5 | D10: =C10 -> 17.5 | E10: =C10 -> 17.5 | F10: =D10 -> 17.5 | G10: # | H10: Ex.1: 70 bookings / 4 hosts
A11: A7 | B11: Pilot host bookings/month after Assured conversion | C11: 20 | D11: =C11 -> 20 | E11: =C11 -> 20 | F11: =D11 -> 20 | G11: # | H11: Ex.3 comparison baseline (20/host)
A12: A8 | B12: Months for pilot hosts to reach target | C12: 3 | D12: =C12 -> 3 | E12: =C12 -> 3 | F12: =D12 -> 3 | G12: months | H12: Team assumption
A13: A9 | B13: Average booking value multiplier | C13: 1 | D13: 0.9 | E13: 1 | F13: =D13 -> 0.9 | G13: x | H13: Downside: 10% price pressure
A14: A10 | B14: Bookings lost to cancellation (beyond tier on-time) | C14: 0 | D14: 0.05 | E14: 0 | F14: =D14 -> 0.05 | G14: % | H14: Downside stress
A15: A11 | B15: Onboarding delay for new hosts | C15: 0 | D15: 2 | E15: 0 | F15: =D15 -> 2 | G15: months | H15: Downside: institutional approvals slip 2 months (Stanford/Science Exchange precedent [S6])
A16: A12 | B16: Fixed cost multiplier | C16: 1 | D16: 1.15 | E16: 1 | F16: =D16 -> 1.15 | G16: x | H16: Downside: 15% overrun
A17: A13 | B17: Current fixed operating cost / month | C17: 360000 | D17: =C17 -> 360000 | E17: =C17 -> 360000 | F17: =D17 -> 360000 | G17: ₹ | H17: Ex.1
A18: A14 | B18: Central trust & quality lead (from month below) | C18: 40000 | D18: =C18 -> 40000 | E18: =C18 -> 40000 | F18: =D18 -> 40000 | G18: ₹/month | H18: Team assumption: 1 hire runs SLA, custody, disputes
A19: A15 | B19: Month central hire starts | C19: 2 | D19: =C19 -> 2 | E19: =C19 -> 2 | F19: =D19 -> 2 | G19: month | H19: Team assumption
A20: A16 | B20: Fixed cost per new city (city partner manager + local ops) | C20: 50000 | D20: =C20 -> 50000 | E20: =C20 -> 50000 | F20: =D20 -> 50000 | G20: ₹/month | H20: Team assumption; added the month before first host goes live
A21: A17 | B21: City 2 (Cluster A) cost starts | C21: 2 | D21: =C21 -> 2 | E21: =C21 -> 2 | F21: =D21 -> 2 | G21: month | H21: Plan
A22: A18 | B22: City 3 (Cluster C) cost starts | C22: 5 | D22: =C22 -> 5 | E22: =C22 -> 5 | F22: =D22 -> 5 | G22: month | H22: Plan
A23: A19 | B23: City 4 (Cluster B) cost starts | C23: 8 | D23: =C23 -> 8 | E23: =C23 -> 8 | F23: =D23 -> 8 | G23: month | H23: Plan
A24: A20 | B24: Assured variable cost after learning | C24: 1200 | D24: =C24 -> 1200 | E24: =C24 -> 1200 | F24: =D24 -> 1200 | G24: ₹/booking | H24: Team assumption: batching, custody kits, scheduling tool cut ₹1,350 by 11%
A25: A21 | B25: Month learning applies from | C25: 10 | D25: =C25 -> 10 | E25: =C25 -> 10 | F25: =D25 -> 10 | G25: month | H25: Team assumption
A26: A22 | B26: Priority SLA: share of Assured bookings | C26: 0.15 | D26: =C26 -> 0.15 | E26: =C26 -> 0.15 | F26: =D26 -> 0.15 | G26: % | H26: Team assumption; 31% of customers cite turnaround (Ex.1)
A27: A23 | B27: Priority SLA: price uplift | C27: 0.5 | D27: =C27 -> 0.5 | E27: =C27 -> 0.5 | F27: =D27 -> 0.5 | G27: % | H27: Evidence: Auriga Research (NABL lab, India) charges a 50% surcharge for express testing [S9]
A28: A24 | B28: Priority SLA: share of uplift OpenBench keeps | C28: 0.5 | D28: =C28 -> 0.5 | E28: =C28 -> 0.5 | F28: =D28 -> 0.5 | G28: % | H28: Other 50% paid to lab/technician pool (host incentive)
... A38: A34 | B38: Onboarding funnel: contact → meeting | C38: 0.3 | D38: =C38 -> 0.3 | E38: =C38 -> 0.3 | F38: =D38 -> 0.3 | G38: % | H38: Team assumption
A39: A35 | B39: Skip Cluster B Verified labs (1 = yes) | C39: 0 | D39: =C39 -> 0 | E39: =C39 -> 0 | F39: 1 | G39: flag | H39: Slide 11 response to "demand below plan" trigger at M9
A40: A36 | B40: City-4 (Cluster B) cost removed from month | C40: 99 | D40: =C40 -> 99 | E40: =C40 -> 99 | F40: 9 | G40: month | H40: Slide 11 response: cut City-4 cost at M9 (99 = never)
A42: Operating tiers (Exhibit 3)
A43: Tier | B43: Take rate | C43: Lab subscription ₹/month | D43: Variable cost ₹/booking | E43: Onboarding ₹/host | F43: On-time target | G43: Exhibit 3 model
A44: Assured | B44: 0.28 | C44: 0 | D44: 1350 | E44: 120000 | F44: 0.94 | G44: B. Managed fulfilment
A45: Connect | B45: 0.08 | C45: 12000 | D45: 400 | E45: 70000 | F45: 0.86 | G45: C. Lab SaaS + booking fee
A46: Verified | B46: 0.18 | C46: 0 | D46: 600 | E46: 45000 | F46: 0.82 | G46: A. Marketplace
A48: Clusters (Exhibit 1 & 2)
A49: Cluster | B49: Potential hosts | C49: Avg booking value ₹ | D49: Mature bookings/host/month | E49: Key issue
A50: Pilot | B50: 4 | C50: 8500 | D50: 20 | E50: Reliability; repeat
A51: A | B51: 5 | C51: 12000 | D51: 24 | E51: IP protection; custom protocols
A52: B | B52: 7 | C52: 6500 | D52: 30 | E52: Price sensitivity; predictable turnaround
...

Sheet Unit Economics
A1: Unit economics by operating model (Exhibit 3) and cluster (Exhibit 2)
A3: Baseline booking value ₹ | C3: 8500 | D3: Ex.3 comparison baseline
A4: Baseline bookings/host/month | C4: 20 | D4: Ex.3 comparison baseline
A6: Model (tier) | B6: Revenue/booking ₹ | C6: Variable cost ₹ | D6: Contribution/booking ₹ | E6: Subscription ₹/host/month | F6: Contribution/host/month ₹ | G6: Onboarding ₹/host | H6: Payback (months)
A7: B. Managed fulfilment (Assured) | B7: =$C$3*Assumptions!B44 -> 2380 | C7: =Assumptions!D44 -> 1350 | D7: =B7-C7 -> 1030 | E7: =Assumptions!C44 -> 0 | F7: =D7*$C$4+E7 -> 20600 | G7: =Assumptions!E44 -> 120000 | H7: =G7/F7 -> 5.8252427
A8: C. Lab SaaS + booking fee (Connect) | B8: =$C$3*Assumptions!B45 -> 680 | C8: =Assumptions!D45 -> 400 | D8: =B8-C8 -> 280 | E8: =Assumptions!C45 -> 12000 | F8: =D8*$C$4+E8 -> 17600 | G8: =Assumptions!E45 -> 70000 | H8: =G8/F8 -> 3.9772727
A9: A. Marketplace (Verified) | B9: =$C$3*Assumptions!B46 -> 1530 | C9: =Assumptions!D46 -> 600 | D9: =B9-C9 -> 930 | E9: =Assumptions!C46 -> 0 | F9: =D9*$C$4+E9 -> 18600 | G9: =Assumptions!E46 -> 45000 | H9: =G9/F9 -> 2.4193548
A11: Pilot today (Marketplace, 18%)
A12: Revenue per booking ₹ | B12: =Assumptions!C50*Assumptions!B46 -> 1530
A13: Contribution per booking ₹ | B13: =B12-Assumptions!D46 -> 930
A14: Bookings per month | B14: =70 -> 70 | C14: Ex.1: 420 bookings / 6 months
A15: Monthly contribution ₹ | B15: =B13*B14 -> 65100
A16: Fixed cost ₹ | B16: =Assumptions!C17 -> 360000
A17: Monthly operating loss ₹ | B17: =B15-B16 -> -294900
A18: Break-even bookings/month at today's fixed cost | B18: =B16/B13 -> 387.09677
A19: Multiple of today's volume | B19: =B18/B14 -> 5.5299539
A22: Cluster × tier (contribution per host per month at mature Exhibit 2 volume, ₹) | B22: Booking value | C22: Bookings/host | D22: Verified (18%) | E22: Assured (28%) | F22: Connect (₹12k + 8%) | G22: Best tier
A23: Cluster A | B23: =Assumptions!C51 -> 12000 | C23: =Assumptions!D51 -> 24 | D23: =C23*(B23*Assumptions!B46-Assumptions!D46) -> 37440 | E23: =C23*(B23*Assumptions!B44-Assumptions!D44) -> 48240 | F23: =C23*(B23*Assumptions!B45-Assumptions!D45)+Assumptions!C45 -> 25440 | G23: =INDEX($D$22:$F$22,MATCH(MAX(D23:F23),D23:F23,0)) -> Assured (28%)
A24: Cluster B | B24: =Assumptions!C52 -> 6500 | C24: =Assumptions!D52 -> 30 | D24: =C24*(B24*Assumptions!B46-Assumptions!D46) -> 17100 | E24: =C24*(B24*Assumptions!B44-Assumptions!D44) -> 14100 | F24: =C24*(B24*Assumptions!B45-Assumptions!D45)+Assumptions!C45 -> 15600 | G24: =INDEX($D$22:$F$22,MATCH(MAX(D24:F24),D24:F24,0)) -> Verified (18%)
A25: Cluster C | B25: =Assumptions!C53 -> 8000 | C25: =Assumptions!D53 -> 26 | D25: =C25*(B25*Assumptions!B46-Assumptions!D46) -> 21840 | E25: =C25*(B25*Assumptions!B44-Assumptions!D44) -> 23140 | F25: =C25*(B25*Assumptions!B45-Assumptions!D45)+Assumptions!C45 -> 18240 | G25: =INDEX($D$22:$F$22,MATCH(MAX(D25:F25),D25:F25,0)) -> Assured (28%)
A27: Reading: Assured wins where booking value and IP sensitivity are high (A, C). In price-sensitive B, Connect charges customers 8% instead of 28% and still earns a subscription floor.
A29: Cluster B break-even point: Connect beats Verified below this many bookings/host/month | B29: =Assumptions!C45/((B24*Assumptions!B46-Assumptions!D46)-(B24*Assumptions!B45-Assumptions!D45)) -> 26.666667 | C29: =B29/C24 -> 0.88888889 | D29: of Exhibit 2 volume → Connect is the safer default for B; labs that refuse a subscription (6 of 10, Ex.3) go on Verified
A31: Why labs join: pilot lab revenue per host per month
A32: Today: marketplace, 17.5 bookings × ₹8,500 × (1 − 18%) | B32: =Assumptions!C10*Assumptions!C50*(1-Assumptions!B46) -> 121975
A33: Assured: 20 bookings × ₹8,500 × (1 − 28% + Priority share to lab) | B33: =Assumptions!C11*Assumptions!C50*(1-Assumptions!B44+Assumptions!C26*Assumptions!C27*(1-Assumptions!C28)) -> 128775
A34: Change for the lab (and OpenBench now does the admin) | B34: =B33/B32-1 -> 0.055749129

Sheet Monthly_Base
A1: Monthly engine — Base scenario (M1–M18)
A2: All values flow from the Assumptions tab. Green = linked input.
A4: ID | B4: Parameter | C4: Value
A5: A1 | B5: =Assumptions!B5 -> Capture of Exhibit 2 mature volume | C5: =Assumptions!C5 -> 0.85
A6: A2 | B6: =Assumptions!B6 -> Ramp: share of mature volume, live month 1 | C6: =Assumptions!C6 -> 0.3
A7: A3 | B7: =Assumptions!B7 -> Ramp: live month 2 | C7: =Assumptions!C7 -> 0.6
A8: A4 | B8: =Assumptions!B8 -> Ramp: live month 3 | C8: =Assumptions!C8 -> 0.85
A9: A5 | B9: =Assumptions!B9 -> Ramp: live month 4+ | C9: =Assumptions!C9 -> 1
A10: A6 | B10: =Assumptions!B10 -> Pilot host bookings/month today | C10: =Assumptions!C10 -> 17.5
A11: A7 | B11: =Assumptions!B11 -> Pilot host bookings/month after Assured conversion | C11: =Assumptions!C11 -> 20
A12: A8 | B12: =Assumptions!B12 -> Months for pilot hosts to reach target | C12: =Assumptions!C12 -> 3
A13: A9 | B13: =Assumptions!B13 -> Average booking value multiplier | C13: =Assumptions!C13 -> 1
A14: A10 | B14: =Assumptions!B14 -> Bookings lost to cancellation (beyond tier on-time) | C14: =Assumptions!C14 -> 0
A15: A11 | B15: =Assumptions!B15 -> Onboarding delay for new hosts | C15: =Assumptions!C15 -> 0
A16: A12 | B16: =Assumptions!B16 -> Fixed cost multiplier | C16: =Assumptions!C16 -> 1
... A40: A36 | B40: =Assumptions!B40 -> City-4 (Cluster B) cost removed from month | C40: =Assumptions!C40 -> 99
A45: Month → | H45: 1 | I45: 2 | J45: 3 | K45: 4 | L45: 5 | M45: 6 | N45: 7 | O45: 8 | P45: 9 | Q45: 10 | R45: 11 | S45: 12 | T45: 13 | U45: 14 | V45: 15 | W45: 16 | X45: 17 | Y45: 18
A47: Bookings per host | B47: Cluster | C47: Tier | D47: Booking value ₹ | E47: Mature/month | F47: Pilot? | G47: Live from month
A48: =Assumptions!A57 -> 1 | B48: =Assumptions!B57 -> Pilot | C48: =Assumptions!C57 -> Assured | D48: =Assumptions!D57 -> 8500 | E48: =Assumptions!E57 -> 20 | F48: =Assumptions!G57 -> 1 | G48: =Assumptions!F57+IF(F48=1,0,$C$15) -> 1 | H48: =IF(H$45<$G48,0,IF($F48=1,$C$10+($C$11-$C$10)*MIN(H$45-$G48,$C$12)/$C$12,$E48*$C$5*INDEX($C$6:$C$9,MIN(H$45-$G48,3)+1)))*(1-$C$14)*IF(AND($C48="Verified",$C$39=1),0,1) -> 17.5 | I48: =IF(I$45<$G48,0,IF($F48=1,$C$10+($C$11-$C$10)*MIN(I$45-$G48,$C$12)/$C$12,$E48*$C$5*INDEX($C$6:$C$9,MIN(I$45-$G48,3)+1)))*(1-$C$14)*IF(AND($C48="Verified",$C$39=1),0,1) -> 18.333333 | J48: =IF(J$45<$G48,0,IF($F48=1,$C$10+($C$11-$C$10)*MIN(J$45-$G48,$C$12)/$C$12,$E48*$C$5*INDEX($C$6:$C$9,MIN(J$45-$G48,3)+1)))*(1-$C$14)*IF(AND($C48="Verified",$C$39=1),0,1) -> 19.166667 | K48: =IF(K$45<$G48,0,IF($F48=1,$C$10+($C$11-$C$10)*MIN(K$45-$G48,$C$12)/$C$12,$E48*$C$5*INDEX($C$6:$C$9,MIN(K$45-$G48,3)+1)))*(1-$C$14)*IF(AND($C48="Verified",$C$39=1),0,1) -> 20 | L48: =IF(L$45<$G48,0,IF($F48=1,$C$10+($C$11-$C$10)*MIN(L$45-$G48,$C$12)/$C$12,$E48*$C$5*INDEX($C$6:$C$9,MIN(L$45-$G48,3)+1)))*(1-$C$14)*IF(AND($C48="Verified",$C$39=1),0,1) -> 20 | M48: =IF(M$45<$G48,0,IF($F48=1,$C$10+($C$11-$C$10)*MIN(M$45-$G48,$C$12)/$C$12,$E48*$C$5*INDEX($C$6:$C$9,MIN(M$45-$G48,3)+1)))*(1-$C$14)*IF(AND($C48="Verified",$C$39=1),0,1) -> 20 | N48: =IF(N$45<$G48,0,IF($F48=1,$C$10+($C$11-$C$10)*MIN(N$45-$G48,$C$12)/$C$12,$E48*$C$5*INDEX($C$6:$C$9,MIN(N$45-$G48,3)+1)))*(1-$C$14)*IF(AND($C48="Verified",$C$39=1),0,1) -> 20 | O48: =IF(O$45<$G48,0,IF($F48=1,$C$10+($C$11-$C$10)*MIN(O$45-$G48,$C$12)/$C$12,$E48*$C$5*INDEX($C$6:$C$9,MIN(O$45-$G48,3)+1)))*(1-$C$14)*IF(AND($C48="Verified",$C$39=1),0,1) -> 20 | ... Y48: =IF(Y$45<$G48,0,IF($F48=1,$C$10+($C$11-$C$10)*MIN(Y$45-$G48,$C$12)/$C$12,$E48*$C$5*INDEX($C$6:$C$9,MIN(Y$45-$G48,3)+1)))*(1-$C$14)*IF(AND($C48="Verified",$C$39=1),0,1) -> 20
A49: =Assumptions!A58 -> 2 | B49: =Assumptions!B58 -> Pilot | C49: =Assumptions!C58 -> Assured | D49: =Assumptions!D58 -> 8500 | E49: =Assumptions!E58 -> 20 | F49: =Assumptions!G58 -> 1 | G49: =Assumptions!F58+IF(F49=1,0,$C$15) -> 1 | H49: =IF(H$45<$G49,0,IF($F49=1,$C$10+($C$11-$C$10)*MIN(H$45-$G49,$C$12)/$C$12,$E49*$C$5*INDEX($C$6:$C$9,MIN(H$45-$G49,3)+1)))*(1-$C$14)*IF(AND($C49="Verified",$C$39=1),0,1) -> 17.5 | I49: =IF(I$45<$G49,0,IF($F49=1,$C$10+($C$11-$C$10)*MIN(I$45-$G49,$C$12)/$C$12,$E49*$C$5*INDEX($C$6:$C$9,MIN(I$45-$G49,3)+1)))*(1-$C$14)*IF(AND($C49="Verified",$C$39=1),0,1) -> 18.333333 | J49: =IF(J$45<$G49,0,IF($F49=1,$C$10+($C$11-$C$10)*MIN(J$45-$G49,$C$12)/$C$12,$E49*$C$5*INDEX($C$6:$C$9,MIN(J$45-$G49,3)+1)))*(1-$C$14)*IF(AND($C49="Verified",$C$39=1),0,1) -> 19.166667 | K49: =IF(K$45<$G49,0,IF($F49=1,$C$10+($C$11-$C$10)*MIN(K$45-$G49,$C$12)/$C$12,$E49*$C$5*INDEX($C$6:$C$9,MIN(K$45-$G49,3)+1)))*(1-$C$14)*IF(AND($C49="Verified",$C$39=1),0,1) -> 20 | L49: =IF(L$45<$G49,0,IF($F49=1,$C$10+($C$11-$C$10)*MIN(L$45-$G49,$C$12)/$C$12,$E49*$C$5*INDEX($C$6:$C$9,MIN(L$45-$G49,3)+1)))*(1-$C$14)*IF(AND($C49="Verified",$C$39=1),0,1) -> 20 | M49: =IF(M$45<$G49,0,IF($F49=1,$C$10+($C$11-$C$10)*MIN(M$45-$G49,$C$12)/$C$12,$E49*$C$5*INDEX($C$6:$C$9,MIN(M$45-$G49,3)+1)))*(1-$C$14)*IF(AND($C49="Verified",$C$39=1),0,1) -> 20 | N49: =IF(N$45<$G49,0,IF($F49=1,$C$10+($C$11-$C$10)*MIN(N$45-$G49,$C$12)/$C$12,$E49*$C$5*INDEX($C$6:$C$9,MIN(N$45-$G49,3)+1)))*(1-$C$14)*IF(AND($C49="Verified",$C$39=1),0,1) -> 20 | O49: =IF(O$45<$G49,0,IF($F49=1,$C$10+($C$11-$C$10)*MIN(O$45-$G49,$C$12)/$C$12,$E49*$C$5*INDEX($C$6:$C$9,MIN(O$45-$G49,3)+1)))*(1-$C$14)*IF(AND($C49="Verified",$C$39=1),0,1) -> 20 | ... Y49: =IF(Y$45<$G49,0,IF($F49=1,$C$10+($C$11-$C$10)*MIN(Y$45-$G49,$C$12)/$C$12,$E49*$C$5*INDEX($C$6:$C$9,MIN(Y$45-$G49,3)+1)))*(1-$C$14)*IF(AND($C49="Verified",$C$39=1),0,1) -> 20
A50: =Assumptions!A59 -> 3 | B50: =Assumptions!B59 -> Pilot | C50: =Assumptions!C59 -> Assured | D50: =Assumptions!D59 -> 8500 | E50: =Assumptions!E59 -> 20 | F50: =Assumptions!G59 -> 1 | G50: =Assumptions!F59+IF(F50=1,0,$C$15) -> 1 | H50: =IF(H$45<$G50,0,IF($F50=1,$C$10+($C$11-$C$10)*MIN(H$45-$G50,$C$12)/$C$12,$E50*$C$5*INDEX($C$6:$C$9,MIN(H$45-$G50,3)+1)))*(1-$C$14)*IF(AND($C50="Verified",$C$39=1),0,1) -> 17.5 | I50: =IF(I$45<$G50,0,IF($F50=1,$C$10+($C$11-$C$10)*MIN(I$45-$G50,$C$12)/$C$12,$E50*$C$5*INDEX($C$6:$C$9,MIN(I$45-$G50,3)+1)))*(1-$C$14)*IF(AND($C50="Verified",$C$39=1),0,1) -> 18.333333 | J50: =IF(J$45<$G50,0,IF($F50=1,$C$10+($C$11-$C$10)*MIN(J$45-$G50,$C$12)/$C$12,$E50*$C$5*INDEX($C$6:$C$9,MIN(J$45-$G50,3)+1)))*(1-$C$14)*IF(AND($C50="Verified",$C$39=1),0,1) -> 19.166667 | K50: =IF(K$45<$G50,0,IF($F50=1,$C$10+($C$11-$C$10)*MIN(K$45-$G50,$C$12)/$C$12,$E50*$C$5*INDEX($C$6:$C$9,MIN(K$45-$G50,3)+1)))*(1-$C$14)*IF(AND($C50="Verified",$C$39=1),0,1) -> 20 | L50: =IF(L$45<$G50,0,IF($F50=1,$C$10+($C$11-$C$10)*MIN(L$45-$G50,$C$12)/$C$12,$E50*$C$5*INDEX($C$6:$C$9,MIN(L$45-$G50,3)+1)))*(1-$C$14)*IF(AND($C50="Verified",$C$39=1),0,1) -> 20 | M50: =IF(M$45<$G50,0,IF($F50=1,$C$10+($C$11-$C$10)*MIN(M$45-$G50,$C$12)/$C$12,$E50*$C$5*INDEX($C$6:$C$9,MIN(M$45-$G50,3)+1)))*(1-$C$14)*IF(AND($C50="Verified",$C$39=1),0,1) -> 20 | N50: =IF(N$45<$G50,0,IF($F50=1,$C$10+($C$11-$C$10)*MIN(N$45-$G50,$C$12)/$C$12,$E50*$C$5*INDEX($C$6:$C$9,MIN(N$45-$G50,3)+1)))*(1-$C$14)*IF(AND($C50="Verified",$C$39=1),0,1) -> 20 | O50: =IF(O$45<$G50,0,IF($F50=1,$C$10+($C$11-$C$10)*MIN(O$45-$G50,$C$12)/$C$12,$E50*$C$5*INDEX($C$6:$C$9,MIN(O$45-$G50,3)+1)))*(1-$C$14)*IF(AND($C50="Verified",$C$39=1),0,1) -> 20 | ... Y50: =IF(Y$45<$G50,0,IF($F50=1,$C$10+($C$11-$C$10)*MIN(Y$45-$G50,$C$12)/$C$12,$E50*$C$5*INDEX($C$6:$C$9,MIN(Y$45-$G50,3)+1)))*(1-$C$14)*IF(AND($C50="Verified",$C$39=1),0,1) -> 20
A51: =Assumptions!A60 -> 4 | B51: =Assumptions!B60 -> Pilot | C51: =Assumptions!C60 -> Assured | D51: =Assumptions!D60 -> 8500 | E51: =Assumptions!E60 -> 20 | F51: =Assumptions!G60 -> 1 | G51: =Assumptions!F60+IF(F51=1,0,$C$15) -> 1 | H51: =IF(H$45<$G51,0,IF($F51=1,$C$10+($C$11-$C$10)*MIN(H$45-$G51,$C$12)/$C$12,$E51*$C$5*INDEX($C$6:$C$9,MIN(H$45-$G51,3)+1)))*(1-$C$14)*IF(AND($C51="Verified",$C$39=1),0,1) -> 17.5 | I51: =IF(I$45<$G51,0,IF($F51=1,$C$10+($C$11-$C$10)*MIN(I$45-$G51,$C$12)/$C$12,$E51*$C$5*INDEX($C$6:$C$9,MIN(I$45-$G51,3)+1)))*(1-$C$14)*IF(AND($C51="Verified",$C$39=1),0,1) -> 18.333333 | J51: =IF(J$45<$G51,0,IF($F51=1,$C$10+($C$11-$C$10)*MIN(J$45-$G51,$C$12)/$C$12,$E51*$C$5*INDEX($C$6:$C$9,MIN(J$45-$G51,3)+1)))*(1-$C$14)*IF(AND($C51="Verified",$C$39=1),0,1) -> 19.166667 | K51: =IF(K$45<$G51,0,IF($F51=1,$C$10+($C$11-$C$10)*MIN(K$45-$G51,$C$12)/$C$12,$E51*$C$5*INDEX($C$6:$C$9,MIN(K$45-$G51,3)+1)))*(1-$C$14)*IF(AND($C51="Verified",$C$39=1),0,1) -> 20 | L51: =IF(L$45<$G51,0,IF($F51=1,$C$10+($C$11-$C$10)*MIN(L$45-$G51,$C$12)/$C$12,$E51*$C$5*INDEX($C$6:$C$9,MIN(L$45-$G51,3)+1)))*(1-$C$14)*IF(AND($C51="Verified",$C$39=1),0,1) -> 20 | M51: =IF(M$45<$G51,0,IF($F51=1,$C$10+($C$11-$C$10)*MIN(M$45-$G51,$C$12)/$C$12,$E51*$C$5*INDEX($C$6:$C$9,MIN(M$45-$G51,3)+1)))*(1-$C$14)*IF(AND($C51="Verified",$C$39=1),0,1) -> 20 | N51: =IF(N$45<$G51,0,IF($F51=1,$C$10+($C$11-$C$10)*MIN(N$45-$G51,$C$12)/$C$12,$E51*$C$5*INDEX($C$6:$C$9,MIN(N$45-$G51,3)+1)))*(1-$C$14)*IF(AND($C51="Verified",$C$39=1),0,1) -> 20 | O51: =IF(O$45<$G51,0,IF($F51=1,$C$10+($C$11-$C$10)*MIN(O$45-$G51,$C$12)/$C$12,$E51*$C$5*INDEX($C$6:$C$9,MIN(O$45-$G51,3)+1)))*(1-$C$14)*IF(AND($C51="Verified",$C$39=1),0,1) -> 20 | ... Y51: =IF(Y$45<$G51,0,IF($F51=1,$C$10+($C$11-$C$10)*MIN(Y$45-$G51,$C$12)/$C$12,$E51*$C$5*INDEX($C$6:$C$9,MIN(Y$45-$G51,3)+1)))*(1-$C$14)*IF(AND($C51="Verified",$C$39=1),0,1) -> 20
A52: =Assumptions!A61 -> 5 | B52: =Assumptions!B61 -> A | C52: =Assumptions!C61 -> Assured | D52: =Assumptions!D61 -> 12000 | E52: =Assumptions!E61 -> 24 | F52: =Assumptions!G61 -> 0 | G52: =Assumptions!F61+IF(F52=1,0,$C$15) -> 3 | H52: =IF(H$45<$G52,0,IF($F52=1,$C$10+($C$11-$C$10)*MIN(H$45-$G52,$C$12)/$C$12,$E52*$C$5*INDEX($C$6:$C$9,MIN(H$45-$G52,3)+1)))*(1-$C$14)*IF(AND($C52="Verified",$C$39=1),0,1) -> 0 | I52: =IF(I$45<$G52,0,IF($F52=1,$C$10+($C$11-$C$10)*MIN(I$45-$G52,$C$12)/$C$12,$E52*$C$5*INDEX($C$6:$C$9,MIN(I$45-$G52,3)+1)))*(1-$C$14)*IF(AND($C52="Verified",$C$39=1),0,1) -> 0 | J52: =IF(J$45<$G52,0,IF($F52=1,$C$10+($C$11-$C$10)*MIN(J$45-$G52,$C$12)/$C$12,$E52*$C$5*INDEX($C$6:$C$9,MIN(J$45-$G52,3)+1)))*(1-$C$14)*IF(AND($C52="Verified",$C$39=1),0,1) -> 6.12 | K52: =IF(K$45<$G52,0,IF($F52=1,$C$10+($C$11-$C$10)*MIN(K$45-$G52,$C$12)/$C$12,$E52*$C$5*INDEX($C$6:$C$9,MIN(K$45-$G52,3)+1)))*(1-$C$14)*IF(AND($C52="Verified",$C$39=1),0,1) -> 12.24 | L52: =IF(L$45<$G52,0,IF($F52=1,$C$10+($C$11-$C$10)*MIN(L$45-$G52,$C$12)/$C$12,$E52*$C$5*INDEX($C$6:$C$9,MIN(L$45-$G52,3)+1)))*(1-$C$14)*IF(AND($C52="Verified",$C$39=1),0,1) -> 17.34 | M52: =IF(M$45<$G52,0,IF($F52=1,$C$10+($C$11-$C$10)*MIN(M$45-$G52,$C$12)/$C$12,$E52*$C$5*INDEX($C$6:$C$9,MIN(M$45-$G52,3)+1)))*(1-$C$14)*IF(AND($C52="Verified",$C$39=1),0,1) -> 20.4 | N52: =IF(N$45<$G52,0,IF($F52=1,$C$10+($C$11-$C$10)*MIN(N$45-$G52,$C$12)/$C$12,$E52*$C$5*INDEX($C$6:$C$9,MIN(N$45-$G52,3)+1)))*(1-$C$14)*IF(AND($C52="Verified",$C$39=1),0,1) -> 20.4 | O52: =IF(O$45<$G52,0,IF($F52=1,$C$10+($C$11-$C$10)*MIN(O$45-$G52,$C$12)/$C$12,$E52*$C$5*INDEX($C$6:$C$9,MIN(O$45-$G52,3)+1)))*(1-$C$14)*IF(AND($C52="Verified",$C$39=1),0,1) -> 20.4 | ... Y52: =IF(Y$45<$G52,0,IF($F52=1,$C$10+($C$11-$C$10)*MIN(Y$45-$G52,$C$12)/$C$12,$E52*$C$5*INDEX($C$6:$C$9,MIN(Y$45-$G52,3)+1)))*(1-$C$14)*IF(AND($C52="Verified",$C$39=1),0,1) -> 20.4
A53: =Assumptions!A62 -> 6 | B53: =Assumptions!B62 -> A | C53: =Assumptions!C62 -> Assured | D53: =Assumptions!D62 -> 12000 | E53: =Assumptions!E62 -> 24 | F53: =Assumptions!G62 -> 0 | G53: =Assumptions!F62+IF(F53=1,0,$C$15) -> 3 | H53: =IF(H$45<$G53,0,IF($F53=1,$C$10+($C$11-$C$10)*MIN(H$45-$G53,$C$12)/$C$12,$E53*$C$5*INDEX($C$6:$C$9,MIN(H$45-$G53,3)+1)))*(1-$C$14)*IF(AND($C53="Verified",$C$39=1),0,1) -> 0 | I53: =IF(I$45<$G53,0,IF($F53=1,$C$10+($C$11-$C$10)*MIN(I$45-$G53,$C$12)/$C$12,$E53*$C$5*INDEX($C$6:$C$9,MIN(I$45-$G53,3)+1)))*(1-$C$14)*IF(AND($C53="Verified",$C$39=1),0,1) -> 0 | J53: =IF(J$45<$G53,0,IF($F53=1,$C$10+($C$11-$C$10)*MIN(J$45-$G53,$C$12)/$C$12,$E53*$C$5*INDEX($C$6:$C$9,MIN(J$45-$G53,3)+1)))*(1-$C$14)*IF(AND($C53="Verified",$C$39=1),0,1) -> 6.12 | K53: =IF(K$45<$G53,0,IF($F53=1,$C$10+($C$11-$C$10)*MIN(K$45-$G53,$C$12)/$C$12,$E53*$C$5*INDEX($C$6:$C$9,MIN(K$45-$G53,3)+1)))*(1-$C$14)*IF(AND($C53="Verified",$C$39=1),0,1) -> 12.24 | L53: =IF(L$45<$G53,0,IF($F53=1,$C$10+($C$11-$C$10)*MIN(L$45-$G53,$C$12)/$C$12,$E53*$C$5*INDEX($C$6:$C$9,MIN(L$45-$G53,3)+1)))*(1-$C$14)*IF(AND($C53="Verified",$C$39=1),0,1) -> 17.34 | M53: =IF(M$45<$G53,0,IF($F53=1,$C$10+($C$11-$C$10)*MIN(M$45-$G53,$C$12)/$C$12,$E53*$C$5*INDEX($C$6:$C$9,MIN(M$45-$G53,3)+1)))*(1-$C$14)*IF(AND($C53="Verified",$C$39=1),0,1) -> 20.4 | N53: =IF(N$45<$G53,0,IF($F53=1,$C$10+($C$11-$C$10)*MIN(N$45-$G53,$C$12)/$C$12,$E53*$C$5*INDEX($C$6:$C$9,MIN(N$45-$G53,3)+1)))*(1-$C$14)*IF(AND($C53="Verified",$C$39=1),0,1) -> 20.4 | O53: =IF(O$45<$G53,0,IF($F53=1,$C$10+($C$11-$C$10)*MIN(O$45-$G53,$C$12)/$C$12,$E53*$C$5*INDEX($C$6:$C$9,MIN(O$45-$G53,3)+1)))*(1-$C$14)*IF(AND($C53="Verified",$C$39=1),0,1) -> 20.4 | ... Y53: =IF(Y$45<$G53,0,IF($F53=1,$C$10+($C$11-$C$10)*MIN(Y$45-$G53,$C$12)/$C$12,$E53*$C$5*INDEX($C$6:$C$9,MIN(Y$45-$G53,3)+1)))*(1-$C$14)*IF(AND($C53="Verified",$C$39=1),0,1) -> 20.4
A54: =Assumptions!A63 -> 7 | B54: =Assumptions!B63 -> A | C54: =Assumptions!C63 -> Assured | D54: =Assumptions!D63 -> 12000 | E54: =Assumptions!E63 -> 24 | F54: =Assumptions!G63 -> 0 | G54: =Assumptions!F63+IF(F54=1,0,$C$15) -> 4 | H54: =IF(H$45<$G54,0,IF($F54=1,$C$10+($C$11-$C$10)*MIN(H$45-$G54,$C$12)/$C$12,$E54*$C$5*INDEX($C$6:$C$9,MIN(H$45-$G54,3)+1)))*(1-$C$14)*IF(AND($C54="Verified",$C$39=1),0,1) -> 0 | I54: =IF(I$45<$G54,0,IF($F54=1,$C$10+($C$11-$C$10)*MIN(I$45-$G54,$C$12)/$C$12,$E54*$C$5*INDEX($C$6:$C$9,MIN(I$45-$G54,3)+1)))*(1-$C$14)*IF(AND($C54="Verified",$C$39=1),0,1) -> 0 | J54: =IF(J$45<$G54,0,IF($F54=1,$C$10+($C$11-$C$10)*MIN(J$45-$G54,$C$12)/$C$12,$E54*$C$5*INDEX($C$6:$C$9,MIN(J$45-$G54,3)+1)))*(1-$C$14)*IF(AND($C54="Verified",$C$39=1),0,1) -> 0 | K54: =IF(K$45<$G54,0,IF($F54=1,$C$10+($C$11-$C$10)*MIN(K$45-$G54,$C$12)/$C$12,$E54*$C$5*INDEX($C$6:$C$9,MIN(K$45-$G54,3)+1)))*(1-$C$14)*IF(AND($C54="Verified",$C$39=1),0,1) -> 6.12 | L54: =IF(L$45<$G54,0,IF($F54=1,$C$10+($C$11-$C$10)*MIN(L$45-$G54,$C$12)/$C$12,$E54*$C$5*INDEX($C$6:$C$9,MIN(L$45-$G54,3)+1)))*(1-$C$14)*IF(AND($C54="Verified",$C$39=1),0,1) -> 12.24 | M54: =IF(M$45<$G54,0,IF($F54=1,$C$10+($C$11-$C$10)*MIN(M$45-$G54,$C$12)/$C$12,$E54*$C$5*INDEX($C$6:$C$9,MIN(M$45-$G54,3)+1)))*(1-$C$14)*IF(AND($C54="Verified",$C$39=1),0,1) -> 17.34 | N54: =IF(N$45<$G54,0,IF($F54=1,$C$10+($C$11-$C$10)*MIN(N$45-$G54,$C$12)/$C$12,$E54*$C$5*INDEX($C$6:$C$9,MIN(N$45-$G54,3)+1)))*(1-$C$14)*IF(AND($C54="Verified",$C$39=1),0,1) -> 20.4 | O54: =IF(O$45<$G54,0,IF($F54=1,$C$10+($C$11-$C$10)*MIN(O$45-$G54,$C$12)/$C$12,$E54*$C$5*INDEX($C$6:$C$9,MIN(O$45-$G54,3)+1)))*(1-$C$14)*IF(AND($C54="Verified",$C$39=1),0,1) -> 20.4 | ... Y54: =IF(Y$45<$G54,0,IF($F54=1,$C$10+($C$11-$C$10)*MIN(Y$45-$G54,$C$12)/$C$12,$E54*$C$5*INDEX($C$6:$C$9,MIN(Y$45-$G54,3)+1)))*(1-$C$14)*IF(AND($C54="Verified",$C$39=1),0,1) -> 20.4
A55: =Assumptions!A64 -> 8 | B55: =Assumptions!B64 -> A | C55: =Assumptions!C64 -> Assured | D55: =Assumptions!D64 -> 12000 | E55: =Assumptions!E64 -> 24 | F55: =Assumptions!G64 -> 0 | G55: =Assumptions!F64+IF(F55=1,0,$C$15) -> 4 | H55: =IF(H$45<$G55,0,IF($F55=1,$C$10+($C$11-$C$10)*MIN(H$45-$G55,$C$12)/$C$12,$E55*$C$5*INDEX($C$6:$C$9,MIN(H$45-$G55,3)+1)))*(1-$C$14)*IF(AND($C55="Verified",$C$39=1),0,1) -> 0 | I55: =IF(I$45<$G55,0,IF($F55=1,$C$10+($C$11-$C$10)*MIN(I$45-$G55,$C$12)/$C$12,$E55*$C$5*INDEX($C$6:$C$9,MIN(I$45-$G55,3)+1)))*(1-$C$14)*IF(AND($C55="Verified",$C$39=1),0,1) -> 0 | J55: =IF(J$45<$G55,0,IF($F55=1,$C$10+($C$11-$C$10)*MIN(J$45-$G55,$C$12)/$C$12,$E55*$C$5*INDEX($C$6:$C$9,MIN(J$45-$G55,3)+1)))*(1-$C$14)*IF(AND($C55="Verified",$C$39=1),0,1) -> 0 | K55: =IF(K$45<$G55,0,IF($F55=1,$C$10+($C$11-$C$10)*MIN(K$45-$G55,$C$12)/$C$12,$E55*$C$5*INDEX($C$6:$C$9,MIN(K$45-$G55,3)+1)))*(1-$C$14)*IF(AND($C55="Verified",$C$39=1),0,1) -> 6.12 | L55: =IF(L$45<$G55,0,IF($F55=1,$C$10+($C$11-$C$10)*MIN(L$45-$G55,$C$12)/$C$12,$E55*$C$5*INDEX($C$6:$C$9,MIN(L$45-$G55,3)+1)))*(1-$C$14)*IF(AND($C55="Verified",$C$39=1),0,1) -> 12.24 | M55: =IF(M$45<$G55,0,IF($F55=1,$C$10+($C$11-$C$10)*MIN(M$45-$G55,$C$12)/$C$12,$E55*$C$5*INDEX($C$6:$C$9,MIN(M$45-$G55,3)+1)))*(1-$C$14)*IF(AND($C55="Verified",$C$39=1),0,1) -> 17.34 | N55: =IF(N$45<$G55,0,IF($F55=1,$C$10+($C$11-$C$10)*MIN(N$45-$G55,$C$12)/$C$12,$E55*$C$5*INDEX($C$6:$C$9,MIN(N$45-$G55,3)+1)))*(1-$C$14)*IF(AND($C55="Verified",$C$39=1),0,1) -> 20.4 | O55: =IF(O$45<$G55,0,IF($F55=1,$C$10+($C$11-$C$10)*MIN(O$45-$G55,$C$12)/$C$12,$E55*$C$5*INDEX($C$6:$C$9,MIN(O$45-$G55,3)+1)))*(1-$C$14)*IF(AND($C55="Verified",$C$39=1),0,1) -> 20.4 | ... Y55: =IF(Y$45<$G55,0,IF($F55=1,$C$10+($C$11-$C$10)*MIN(Y$45-$G55,$C$12)/$C$12,$E55*$C$5*INDEX($C$6:$C$9,MIN(Y$45-$G55,3)+1)))*(1-$C$14)*IF(AND($C55="Verified",$C$39=1),0,1) -> 20.4
A56: =Assumptions!A65 -> 9 | B56: =Assumptions!B65 -> A | C56: =Assumptions!C65 -> Assured | D56: =Assumptions!D65 -> 12000 | E56: =Assumptions!E65 -> 24 | F56: =Assumptions!G65 -> 0 | G56: =Assumptions!F65+IF(F56=1,0,$C$15) -> 5 | H56: =IF(H$45<$G56,0,IF($F56=1,$C$10+($C$11-$C$10)*MIN(H$45-$G56,$C$12)/$C$12,$E56*$C$5*INDEX($C$6:$C$9,MIN(H$45-$G56,3)+1)))*(1-$C$14)*IF(AND($C56="Verified",$C$39=1),0,1) -> 0 | I56: =IF(I$45<$G56,0,IF($F56=1,$C$10+($C$11-$C$10)*MIN(I$45-$G56,$C$12)/$C$12,$E56*$C$5*INDEX($C$6:$C$9,MIN(I$45-$G56,3)+1)))*(1-$C$14)*IF(AND($C56="Verified",$C$39=1),0,1) -> 0 | J56: =IF(J$45<$G56,0,IF($F56=1,$C$10+($C$11-$C$10)*MIN(J$45-$G56,$C$12)/$C$12,$E56*$C$5*INDEX($C$6:$C$9,MIN(J$45-$G56,3)+1)))*(1-$C$14)*IF(AND($C56="Verified",$C$39=1),0,1) -> 0 | K56: =IF(K$45<$G56,0,IF($F56=1,$C$10+($C$11-$C$10)*MIN(K$45-$G56,$C$12)/$C$12,$E56*$C$5*INDEX($C$6:$C$9,MIN(K$45-$G56,3)+1)))*(1-$C$14)*IF(AND($C56="Verified",$C$39=1),0,1) -> 0 | L56: =IF(L$45<$G56,0,IF($F56=1,$C$10+($C$11-$C$10)*MIN(L$45-$G56,$C$12)/$C$12,$E56*$C$5*INDEX($C$6:$C$9,MIN(L$45-$G56,3)+1)))*(1-$C$14)*IF(AND($C56="Verified",$C$39=1),0,1) -> 6.12 | M56: =IF(M$45<$G56,0,IF($F56=1,$C$10+($C$11-$C$10)*MIN(M$45-$G56,$C$12)/$C$12,$E56*$C$5*INDEX($C$6:$C$9,MIN(M$45-$G56,3)+1)))*(1-$C$14)*IF(AND($C56="Verified",$C$39=1),0,1) -> 12.24 | N56: =IF(N$45<$G56,0,IF($F56=1,$C$10+($C$11-$C$10)*MIN(N$45-$G56,$C$12)/$C$12,$E56*$C$5*INDEX($C$6:$C$9,MIN(N$45-$G56,3)+1)))*(1-$C$14)*IF(AND($C56="Verified",$C$39=1),0,1) -> 17.34 | O56: =IF(O$45<$G56,0,IF($F56=1,$C$10+($C$11-$C$10)*MIN(O$45-$G56,$C$12)/$C$12,$E56*$C$5*INDEX($C$6:$C$9,MIN(O$45-$G56,3)+1)))*(1-$C$14)*IF(AND($C56="Verified",$C$39=1),0,1) -> 20.4 | ... Y56: =IF(Y$45<$G56,0,IF($F56=1,$C$10+($C$11-$C$10)*MIN(Y$45-$G56,$C$12)/$C$12,$E56*$C$5*INDEX($C$6:$C$9,MIN(Y$45-$G56,3)+1)))*(1-$C$14)*IF(AND($C56="Verified",$C$39=1),0,1) -> 20.4
A57: =Assumptions!A66 -> 10 | B57: =Assumptions!B66 -> C | C57: =Assumptions!C66 -> Assured | D57: =Assumptions!D66 -> 8000 | E57: =Assumptions!E66 -> 26 | F57: =Assumptions!G66 -> 0 | G57: =Assumptions!F66+IF(F57=1,0,$C$15) -> 6 | H57: =IF(H$45<$G57,0,IF($F57=1,$C$10+($C$11-$C$10)*MIN(H$45-$G57,$C$12)/$C$12,$E57*$C$5*INDEX($C$6:$C$9,MIN(H$45-$G57,3)+1)))*(1-$C$14)*IF(AND($C57="Verified",$C$39=1),0,1) -> 0 | I57: =IF(I$45<$G57,0,IF($F57=1,$C$10+($C$11-$C$10)*MIN(I$45-$G57,$C$12)/$C$12,$E57*$C$5*INDEX($C$6:$C$9,MIN(I$45-$G57,3)+1)))*(1-$C$14)*IF(AND($C57="Verified",$C$39=1),0,1) -> 0 | J57: =IF(J$45<$G57,0,IF($F57=1,$C$10+($C$11-$C$10)*MIN(J$45-$G57,$C$12)/$C$12,$E57*$C$5*INDEX($C$6:$C$9,MIN(J$45-$G57,3)+1)))*(1-$C$14)*IF(AND($C57="Verified",$C$39=1),0,1) -> 0 | K57: =IF(K$45<$G57,0,IF($F57=1,$C$10+($C$11-$C$10)*MIN(K$45-$G57,$C$12)/$C$12,$E57*$C$5*INDEX($C$6:$C$9,MIN(K$45-$G57,3)+1)))*(1-$C$14)*IF(AND($C57="Verified",$C$39=1),0,1) -> 0 | L57: =IF(L$45<$G57,0,IF($F57=1,$C$10+($C$11-$C$10)*MIN(L$45-$G57,$C$12)/$C$12,$E57*$C$5*INDEX($C$6:$C$9,MIN(L$45-$G57,3)+1)))*(1-$C$14)*IF(AND($C57="Verified",$C$39=1),0,1) -> 0 | M57: =IF(M$45<$G57,0,IF($F57=1,$C$10+($C$11-$C$10)*MIN(M$45-$G57,$C$12)/$C$12,$E57*$C$5*INDEX($C$6:$C$9,MIN(M$45-$G57,3)+1)))*(1-$C$14)*IF(AND($C57="Verified",$C$39=1),0,1) -> 6.63 | N57: =IF(N$45<$G57,0,IF($F57=1,$C$10+($C$11-$C$10)*MIN(N$45-$G57,$C$12)/$C$12,$E57*$C$5*INDEX($C$6:$C$9,MIN(N$45-$G57,3)+1)))*(1-$C$14)*IF(AND($C57="Verified",$C$39=1),0,1) -> 13.26 | O57: =IF(O$45<$G57,0,IF($F57=1,$C$10+($C$11-$C$10)*MIN(O$45-$G57,$C$12)/$C$12,$E57*$C$5*INDEX($C$6:$C$9,MIN(O$45-$G57,3)+1)))*(1-$C$14)*IF(AND($C57="Verified",$C$39=1),0,1) -> 18.785 | ... Y57: =IF(Y$45<$G57,0,IF($F57=1,$C$10+($C$11-$C$10)*MIN(Y$45-$G57,$C$12)/$C$12,$E57*$C$5*INDEX($C$6:$C$9,MIN(Y$45-$G57,3)+1)))*(1-$C$14)*IF(AND($C57="Verified",$C$39=1),0,1) -> 22.1
A58: =Assumptions!A67 -> 11 | B58: =Assumptions!B67 -> C | C58: =Assumptions!C67 -> Assured | D58: =Assumptions!D67 -> 8000 | E58: =Assumptions!E67 -> 26 | F58: =Assumptions!G67 -> 0 | G58: =Assumptions!F67+IF(F58=1,0,$C$15) -> 7 | H58: =IF(H$45<$G58,0,IF($F58=1,$C$10+($C$11-$C$10)*MIN(H$45-$G58,$C$12)/$C$12,$E58*$C$5*INDEX($C$6:$C$9,MIN(H$45-$G58,3)+1)))*(1-$C$14)*IF(AND($C58="Verified",$C$39=1),0,1) -> 0 | I58: =IF(I$45<$G58,0,IF($F58=1,$C$10+($C$11-$C$10)*MIN(I$45-$G58,$C$12)/$C$12,$E58*$C$5*INDEX($C$6:$C$9,MIN(I$45-$G58,3)+1)))*(1-$C$14)*IF(AND($C58="Verified",$C$39=1),0,1) -> 0 | J58: =IF(J$45<$G58,0,IF($F58=1,$C$10+($C$11-$C$10)*MIN(J$45-$G58,$C$12)/$C$12,$E58*$C$5*INDEX($C$6:$C$9,MIN(J$45-$G58,3)+1)))*(1-$C$14)*IF(AND($C58="Verified",$C$39=1),0,1) -> 0 | K58: =IF(K$45<$G58,0,IF($F58=1,$C$10+($C$11-$C$10)*MIN(K$45-$G58,$C$12)/$C$12,$E58*$C$5*INDEX($C$6:$C$9,MIN(K$45-$G58,3)+1)))*(1-$C$14)*IF(AND($C58="Verified",$C$39=1),0,1) -> 0 | L58: =IF(L$45<$G58,0,IF($F58=1,$C$10+($C$11-$C$10)*MIN(L$45-$G58,$C$12)/$C$12,$E58*$C$5*INDEX($C$6:$C$9,MIN(L$45-$G58,3)+1)))*(1-$C$14)*IF(AND($C58="Verified",$C$39=1),0,1) -> 0 | M58: =IF(M$45<$G58,0,IF($F58=1,$C$10+($C$11-$C$10)*MIN(M$45-$G58,$C$12)/$C$12,$E58*$C$5*INDEX($C$6:$C$9,MIN(M$45-$G58,3)+1)))*(1-$C$14)*IF(AND($C58="Verified",$C$39=1),0,1) -> 0 | N58: =IF(N$45<$G58,0,IF($F58=1,$C$10+($C$11-$C$10)*MIN(N$45-$G58,$C$12)/$C$12,$E58*$C$5*INDEX($C$6:$C$9,MIN(N$45-$G58,3)+1)))*(1-$C$14)*IF(AND($C58="Verified",$C$39=1),0,1) -> 6.63 | O58: =IF(O$45<$G58,0,IF($F58=1,$C$10+($C$11-$C$10)*MIN(O$45-$G58,$C$12)/$C$12,$E58*$C$5*INDEX($C$6:$C$9,MIN(O$45-$G58,3)+1)))*(1-$C$14)*IF(AND($C58="Verified",$C$39=1),0,1) -> 13.26 | ... Y58: =IF(Y$45<$G58,0,IF($F58=1,$C$10+($C$11-$C$10)*MIN(Y$45-$G58,$C$12)/$C$12,$E58*$C$5*INDEX($C$6:$C$9,MIN(Y$45-$G58,3)+1)))*(1-$C$14)*IF(AND($C58="Verified",$C$39=1),0,1) -> 22.1
A59: =Assumptions!A68 -> 12 | B59: =Assumptions!B68 -> C | C59: =Assumptions!C68 -> Assured | D59: =Assumptions!D68 -> 8000 | E59: =Assumptions!E68 -> 26 | F59: =Assumptions!G68 -> 0 | G59: =Assumptions!F68+IF(F59=1,0,$C$15) -> 7 | H59: =IF(H$45<$G59,0,IF($F59=1,$C$10+($C$11-$C$10)*MIN(H$45-$G59,$C$12)/$C$12,$E59*$C$5*INDEX($C$6:$C$9,MIN(H$45-$G59,3)+1)))*(1-$C$14)*IF(AND($C59="Verified",$C$39=1),0,1) -> 0 | I59: =IF(I$45<$G59,0,IF($F59=1,$C$10+($C$11-$C$10)*MIN(I$45-$G59,$C$12)/$C$12,$E59*$C$5*INDEX($C$6:$C$9,MIN(I$45-$G59,3)+1)))*(1-$C$14)*IF(AND($C59="Verified",$C$39=1),0,1) -> 0 | J59: =IF(J$45<$G59,0,IF($F59=1,$C$10+($C$11-$C$10)*MIN(J$45-$G59,$C$12)/$C$12,$E59*$C$5*INDEX($C$6:$C$9,MIN(J$45-$G59,3)+1)))*(1-$C$14)*IF(AND($C59="Verified",$C$39=1),0,1) -> 0 | K59: =IF(K$45<$G59,0,IF($F59=1,$C$10+($C$11-$C$10)*MIN(K$45-$G59,$C$12)/$C$12,$E59*$C$5*INDEX($C$6:$C$9,MIN(K$45-$G59,3)+1)))*(1-$C$14)*IF(AND($C59="Verified",$C$39=1),0,1) -> 0 | L59: =IF(L$45<$G59,0,IF($F59=1,$C$10+($C$11-$C$10)*MIN(L$45-$G59,$C$12)/$C$12,$E59*$C$5*INDEX($C$6:$C$9,MIN(L$45-$G59,3)+1)))*(1-$C$14)*IF(AND($C59="Verified",$C$39=1),0,1) -> 0 | M59: =IF(M$45<$G59,0,IF($F59=1,$C$10+($C$11-$C$10)*MIN(M$45-$G59,$C$12)/$C$12,$E59*$C$5*INDEX($C$6:$C$9,MIN(M$45-$G59,3)+1)))*(1-$C$14)*IF(AND($C59="Verified",$C$39=1),0,1) -> 0 | N59: =IF(N$45<$G59,0,IF($F59=1,$C$10+($C$11-$C$10)*MIN(N$45-$G59,$C$12)/$C$12,$E59*$C$5*INDEX($C$6:$C$9,MIN(N$45-$G59,3)+1)))*(1-$C$14)*IF(AND($C59="Verified",$C$39=1),0,1) -> 6.63 | O59: =IF(O$45<$G59,0,IF($F59=1,$C$10+($C$11-$C$10)*MIN(O$45-$G59,$C$12)/$C$12,$E59*$C$5*INDEX($C$6:$C$9,MIN(O$45-$G59,3)+1)))*(1-$C$14)*IF(AND($C59="Verified",$C$39=1),0,1) -> 13.26 | ... Y59: =IF(Y$45<$G59,0,IF($F59=1,$C$10+($C$11-$C$10)*MIN(Y$45-$G59,$C$12)/$C$12,$E59*$C$5*INDEX($C$6:$C$9,MIN(Y$45-$G59,3)+1)))*(1-$C$14)*IF(AND($C59="Verified",$C$39=1),0,1) -> 22.1
... A67: =Assumptions!A76 -> 20 | B67: =Assumptions!B76 -> B | C67: =Assumptions!C76 -> Verified | D67: =Assumptions!D76 -> 6500 | E67: =Assumptions!E76 -> 30 | F67: =Assumptions!G76 -> 0 | G67: =Assumptions!F76+IF(F67=1,0,$C$15) -> 14 | H67: =IF(H$45<$G67,0,IF($F67=1,$C$10+($C$11-$C$10)*MIN(H$45-$G67,$C$12)/$C$12,$E67*$C$5*INDEX($C$6:$C$9,MIN(H$45-$G67,3)+1)))*(1-$C$14)*IF(AND($C67="Verified",$C$39=1),0,1) -> 0 | I67: =IF(I$45<$G67,0,IF($F67=1,$C$10+($C$11-$C$10)*MIN(I$45-$G67,$C$12)/$C$12,$E67*$C$5*INDEX($C$6:$C$9,MIN(I$45-$G67,3)+1)))*(1-$C$14)*IF(AND($C67="Verified",$C$39=1),0,1) -> 0 | J67: =IF(J$45<$G67,0,IF($F67=1,$C$10+($C$11-$C$10)*MIN(J$45-$G67,$C$12)/$C$12,$E67*$C$5*INDEX($C$6:$C$9,MIN(J$45-$G67,3)+1)))*(1-$C$14)*IF(AND($C67="Verified",$C$39=1),0,1) -> 0 | K67: =IF(K$45<$G67,0,IF($F67=1,$C$10+($C$11-$C$10)*MIN(K$45-$G67,$C$12)/$C$12,$E67*$C$5*INDEX($C$6:$C$9,MIN(K$45-$G67,3)+1)))*(1-$C$14)*IF(AND($C67="Verified",$C$39=1),0,1) -> 0 | L67: =IF(L$45<$G67,0,IF($F67=1,$C$10+($C$11-$C$10)*MIN(L$45-$G67,$C$12)/$C$12,$E67*$C$5*INDEX($C$6:$C$9,MIN(L$45-$G67,3)+1)))*(1-$C$14)*IF(AND($C67="Verified",$C$39=1),0,1) -> 0 | M67: =IF(M$45<$G67,0,IF($F67=1,$C$10+($C$11-$C$10)*MIN(M$45-$G67,$C$12)/$C$12,$E67*$C$5*INDEX($C$6:$C$9,MIN(M$45-$G67,3)+1)))*(1-$C$14)*IF(AND($C67="Verified",$C$39=1),0,1) -> 0 | N67: =IF(N$45<$G67,0,IF($F67=1,$C$10+($C$11-$C$10)*MIN(N$45-$G67,$C$12)/$C$12,$E67*$C$5*INDEX($C$6:$C$9,MIN(N$45-$G67,3)+1)))*(1-$C$14)*IF(AND($C67="Verified",$C$39=1),0,1) -> 0 | O67: =IF(O$45<$G67,0,IF($F67=1,$C$10+($C$11-$C$10)*MIN(O$45-$G67,$C$12)/$C$12,$E67*$C$5*INDEX($C$6:$C$9,MIN(O$45-$G67,3)+1)))*(1-$C$14)*IF(AND($C67="Verified",$C$39=1),0,1) -> 0 | ... Y67: =IF(Y$45<$G67,0,IF($F67=1,$C$10+($C$11-$C$10)*MIN(Y$45-$G67,$C$12)/$C$12,$E67*$C$5*INDEX($C$6:$C$9,MIN(Y$45-$G67,3)+1)))*(1-$C$14)*IF(AND($C67="Verified",$C$39=1),0,1) -> 25.5
A69: OpenBench revenue per host (₹)
A70: =A48 -> 1 | B70: =B48 -> Pilot | C70: =C48 -> Assured | H70: =H48*$D48*$C$13*INDEX(Assumptions!$B$44:$B$46,MATCH($C48,Assumptions!$A$44:$A$46,0))+IF(H$45>=$G48,INDEX(Assumptions!$C$44:$C$46,MATCH($C48,Assumptions!$A$44:$A$46,0)),0)+IF($C48="Assured",H48*$D48*$C$13*$C$26*$C$27*$C$28,0) -> 47228.125 | I70: =I48*$D48*$C$13*INDEX(Assumptions!$B$44:$B$46,MATCH($C48,Assumptions!$A$44:$A$46,0))+IF(I$45>=$G48,INDEX(Assumptions!$C$44:$C$46,MATCH($C48,Assumptions!$A$44:$A$46,0)),0)+IF($C48="Assured",I48*$D48*$C$13*$C$26*$C$27*$C$28,0) -> 49477.083 | J70: =J48*$D48*$C$13*INDEX(Assumptions!$B$44:$B$46,MATCH($C48,Assumptions!$A$44:$A$46,0))+IF(J$45>=$G48,INDEX(Assumptions!$C$44:$C$46,MATCH($C48,Assumptions!$A$44:$A$46,0)),0)+IF($C48="Assured",J48*$D48*$C$13*$C$26*$C$27*$C$28,0) -> 51726.042 | K70: =K48*$D48*$C$13*INDEX(Assumptions!$B$44:$B$46,MATCH($C48,Assumptions!$A$44:$A$46,0))+IF(K$45>=$G48,INDEX(Assumptions!$C$44:$C$46,MATCH($C48,Assumptions!$A$44:$A$46,0)),0)+IF($C48="Assured",K48*$D48*$C$13*$C$26*$C$27*$C$28,0) -> 53975 | L70: =L48*$D48*$C$13*INDEX(Assumptions!$B$44:$B$46,MATCH($C48,Assumptions!$A$44:$A$46,0))+IF(L$45>=$G48,INDEX(Assumptions!$C$44:$C$46,MATCH($C48,Assumptions!$A$44:$A$46,0)),0)+IF($C48="Assured",L48*$D48*$C$13*$C$26*$C$27*$C$28,0) -> 53975 | M70: =M48*$D48*$C$13*INDEX(Assumptions!$B$44:$B$46,MATCH($C48,Assumptions!$A$44:$A$46,0))+IF(M$45>=$G48,INDEX(Assumptions!$C$44:$C$46,MATCH($C48,Assumptions!$A$44:$A$46,0)),0)+IF($C48="Assured",M48*$D48*$C$13*$C$26*$C$27*$C$28,0) -> 53975 | N70: =N48*$D48*$C$13*INDEX(Assumptions!$B$44:$B$46,MATCH($C48,Assumptions!$A$44:$A$46,0))+IF(N$45>=$G48,INDEX(Assumptions!$C$44:$C$46,MATCH($C48,Assumptions!$A$44:$A$46,0)),0)+IF($C48="Assured",N48*$D48*$C$13*$C$26*$C$27*$C$28,0) -> 53975 | O70: =O48*$D48*$C$13*INDEX(Assumptions!$B$44:$B$46,MATCH($C48,Assumptions!$A$44:$A$46,0))+IF(O$45>=$G48,INDEX(Assumptions!$C$44:$C$46,MATCH($C48,Assumptions!$A$44:$A$46,0)),0)+IF($C48="Assured",O48*$D48*$C$13*$C$26*$C$27*$C$28,0) -> 53975 | ... Y70: =Y48*$D48*$C$13*INDEX(Assumptions!$B$44:$B$46,MATCH($C48,Assumptions!$A$44:$A$46,0))+IF(Y$45>=$G48,INDEX(Assumptions!$C$44:$C$46,MATCH($C48,Assumptions!$A$44:$A$46,0)),0)+IF($C48="Assured",Y48*$D48*$C$13*$C$26*$C$27*$C$28,0) -> 53975
A71: =A49 -> 2 | B71: =B49 -> Pilot | C71: =C49 -> Assured | H71: =H49*$D49*$C$13*INDEX(Assumptions!$B$44:$B$46,MATCH($C49,Assumptions!$A$44:$A$46,0))+IF(H$45>=$G49,INDEX(Assumptions!$C$44:$C$46,MATCH($C49,Assumptions!$A$44:$A$46,0)),0)+IF($C49="Assured",H49*$D49*$C$13*$C$26*$C$27*$C$28,0) -> 47228.125 | I71: =I49*$D49*$C$13*INDEX(Assumptions!$B$44:$B$46,MATCH($C49,Assumptions!$A$44:$A$46,0))+IF(I$45>=$G49,INDEX(Assumptions!$C$44:$C$46,MATCH($C49,Assumptions!$A$44:$A$46,0)),0)+IF($C49="Assured",I49*$D49*$C$13*$C$26*$C$27*$C$28,0) -> 49477.083 | J71: =J49*$D49*$C$13*INDEX(Assumptions!$B$44:$B$46,MATCH($C49,Assumptions!$A$44:$A$46,0))+IF(J$45>=$G49,INDEX(Assumptions!$C$44:$C$46,MATCH($C49,Assumptions!$A$44:$A$46,0)),0)+IF($C49="Assured",J49*$D49*$C$13*$C$26*$C$27*$C$28,0) -> 51726.042 | K71: =K49*$D49*$C$13*INDEX(Assumptions!$B$44:$B$46,MATCH($C49,Assumptions!$A$44:$A$46,0))+IF(K$45>=$G49,INDEX(Assumptions!$C$44:$C$46,MATCH($C49,Assumptions!$A$44:$A$46,0)),0)+IF($C49="Assured",K49*$D49*$C$13*$C$26*$C$27*$C$28,0) -> 53975 | L71: =L49*$D49*$C$13*INDEX(Assumptions!$B$44:$B$46,MATCH($C49,Assumptions!$A$44:$A$46,0))+IF(L$45>=$G49,INDEX(Assumptions!$C$44:$C$46,MATCH($C49,Assumptions!$A$44:$A$46,0)),0)+IF($C49="Assured",L49*$D49*$C$13*$C$26*$C$27*$C$28,0) -> 53975 | M71: =M49*$D49*$C$13*INDEX(Assumptions!$B$44:$B$46,MATCH($C49,Assumptions!$A$44:$A$46,0))+IF(M$45>=$G49,INDEX(Assumptions!$C$44:$C$46,MATCH($C49,Assumptions!$A$44:$A$46,0)),0)+IF($C49="Assured",M49*$D49*$C$13*$C$26*$C$27*$C$28,0) -> 53975 | N71: =N49*$D49*$C$13*INDEX(Assumptions!$B$44:$B$46,MATCH($C49,Assumptions!$A$44:$A$46,0))+IF(N$45>=$G49,INDEX(Assumptions!$C$44:$C$46,MATCH($C49,Assumptions!$A$44:$A$46,0)),0)+IF($C49="Assured",N49*$D49*$C$13*$C$26*$C$27*$C$28,0) -> 53975 | O71: =O49*$D49*$C$13*INDEX(Assumptions!$B$44:$B$46,MATCH($C49,Assumptions!$A$44:$A$46,0))+IF(O$45>=$G49,INDEX(Assumptions!$C$44:$C$46,MATCH($C49,Assumptions!$A$44:$A$46,0)),0)+IF($C49="Assured",O49*$D49*$C$13*$C$26*$C$27*$C$28,0) -> 53975 | ... Y71: =Y49*$D49*$C$13*INDEX(Assumptions!$B$44:$B$46,MATCH($C49,Assumptions!$A$44:$A$46,0))+IF(Y$45>=$G49,INDEX(Assumptions!$C$44:$C$46,MATCH($C49,Assumptions!$A$44:$A$46,0)),0)+IF($C49="Assured",Y49*$D49*$C$13*$C$26*$C$27*$C$28,0) -> 53975
A72: =A50 -> 3 | B72: =B50 -> Pilot | C72: =C50 -> Assured | H72: =H50*$D50*$C$13*INDEX(Assumptions!$B$44:$B$46,MATCH($C50,Assumptions!$A$44:$A$46,0))+IF(H$45>=$G50,INDEX(Assumptions!$C$44:$C$46,MATCH($C50,Assumptions!$A$44:$A$46,0)),0)+IF($C50="Assured",H50*$D50*$C$13*$C$26*$C$27*$C$28,0) -> 47228.125 | I72: =I50*$D50*$C$13*INDEX(Assumptions!$B$44:$B$46,MATCH($C50,Assumptions!$A$44:$A$46,0))+IF(I$45>=$G50,INDEX(Assumptions!$C$44:$C$46,MATCH($C50,Assumptions!$A$44:$A$46,0)),0)+IF($C50="Assured",I50*$D50*$C$13*$C$26*$C$27*$C$28,0) -> 49477.083 | J72: =J50*$D50*$C$13*INDEX(Assumptions!$B$44:$B$46,MATCH($C50,Assumptions!$A$44:$A$46,0))+IF(J$45>=$G50,INDEX(Assumptions!$C$44:$C$46,MATCH($C50,Assumptions!$A$44:$A$46,0)),0)+IF($C50="Assured",J50*$D50*$C$13*$C$26*$C$27*$C$28,0) -> 51726.042 | K72: =K50*$D50*$C$13*INDEX(Assumptions!$B$44:$B$46,MATCH($C50,Assumptions!$A$44:$A$46,0))+IF(K$45>=$G50,INDEX(Assumptions!$C$44:$C$46,MATCH($C50,Assumptions!$A$44:$A$46,0)),0)+IF($C50="Assured",K50*$D50*$C$13*$C$26*$C$27*$C$28,0) -> 53975 | L72: =L50*$D50*$C$13*INDEX(Assumptions!$B$44:$B$46,MATCH($C50,Assumptions!$A$44:$A$46,0))+IF(L$45>=$G50,INDEX(Assumptions!$C$44:$C$46,MATCH($C50,Assumptions!$A$44:$A$46,0)),0)+IF($C50="Assured",L50*$D50*$C$13*$C$26*$C$27*$C$28,0) -> 53975 | M72: =M50*$D50*$C$13*INDEX(Assumptions!$B$44:$B$46,MATCH($C50,Assumptions!$A$44:$A$46,0))+IF(M$45>=$G50,INDEX(Assumptions!$C$44:$C$46,MATCH($C50,Assumptions!$A$44:$A$46,0)),0)+IF($C50="Assured",M50*$D50*$C$13*$C$26*$C$27*$C$28,0) -> 53975 | N72: =N50*$D50*$C$13*INDEX(Assumptions!$B$44:$B$46,MATCH($C50,Assumptions!$A$44:$A$46,0))+IF(N$45>=$G50,INDEX(Assumptions!$C$44:$C$46,MATCH($C50,Assumptions!$A$44:$A$46,0)),0)+IF($C50="Assured",N50*$D50*$C$13*$C$26*$C$27*$C$28,0) -> 53975 | O72: =O50*$D50*$C$13*INDEX(Assumptions!$B$44:$B$46,MATCH($C50,Assumptions!$A$44:$A$46,0))+IF(O$45>=$G50,INDEX(Assumptions!$C$44:$C$46,MATCH($C50,Assumptions!$A$44:$A$46,0)),0)+IF($C50="Assured",O50*$D50*$C$13*$C$26*$C$27*$C$28,0) -> 53975 | ... Y72: =Y50*$D50*$C$13*INDEX(Assumptions!$B$44:$B$46,MATCH($C50,Assumptions!$A$44:$A$46,0))+IF(Y$45>=$G50,INDEX(Assumptions!$C$44:$C$46,MATCH($C50,Assumptions!$A$44:$A$46,0)),0)+IF($C50="Assured",Y50*$D50*$C$13*$C$26*$C$27*$C$28,0) -> 53975
A73: =A51 -> 4 | B73: =B51 -> Pilot | C73: =C51 -> Assured | H73: =H51*$D51*$C$13*INDEX(Assumptions!$B$44:$B$46,MATCH($C51,Assumptions!$A$44:$A$46,0))+IF(H$45>=$G51,INDEX(Assumptions!$C$44:$C$46,MATCH($C51,Assumptions!$A$44:$A$46,0)),0)+IF($C51="Assured",H51*$D51*$C$13*$C$26*$C$27*$C$28,0) -> 47228.125 | I73: =I51*$D51*$C$13*INDEX(Assumptions!$B$44:$B$46,MATCH($C51,Assumptions!$A$44:$A$46,0))+IF(I$45>=$G51,INDEX(Assumptions!$C$44:$C$46,MATCH($C51,Assumptions!$A$44:$A$46,0)),0)+IF($C51="Assured",I51*$D51*$C$13*$C$26*$C$27*$C$28,0) -> 49477.083 | J73: =J51*$D51*$C$13*INDEX(Assumptions!$B$44:$B$46,MATCH($C51,Assumptions!$A$44:$A$46,0))+IF(J$45>=$G51,INDEX(Assumptions!$C$44:$C$46,MATCH($C51,Assumptions!$A$44:$A$46,0)),0)+IF($C51="Assured",J51*$D51*$C$13*$C$26*$C$27*$C$28,0) -> 51726.042 | K73: =K51*$D51*$C$13*INDEX(Assumptions!$B$44:$B$46,MATCH($C51,Assumptions!$A$44:$A$46,0))+IF(K$45>=$G51,INDEX(Assumptions!$C$44:$C$46,MATCH($C51,Assumptions!$A$44:$A$46,0)),0)+IF($C51="Assured",K51*$D51*$C$13*$C$26*$C$27*$C$28,0) -> 53975 | L73: =L51*$D51*$C$13*INDEX(Assumptions!$B$44:$B$46,MATCH($C51,Assumptions!$A$44:$A$46,0))+IF(L$45>=$G51,INDEX(Assumptions!$C$44:$C$46,MATCH($C51,Assumptions!$A$44:$A$46,0)),0)+IF($C51="Assured",L51*$D51*$C$13*$C$26*$C$27*$C$28,0) -> 53975 | M73: =M51*$D51*$C$13*INDEX(Assumptions!$B$44:$B$46,MATCH($C51,Assumptions!$A$44:$A$46,0))+IF(M$45>=$G51,INDEX(Assumptions!$C$44:$C$46,MATCH($C51,Assumptions!$A$44:$A$46,0)),0)+IF($C51="Assured",M51*$D51*$C$13*$C$26*$C$27*$C$28,0) -> 53975 | N73: =N51*$D51*$C$13*INDEX(Assumptions!$B$44:$B$46,MATCH($C51,Assumptions!$A$44:$A$46,0))+IF(N$45>=$G51,INDEX(Assumptions!$C$44:$C$46,MATCH($C51,Assumptions!$A$44:$A$46,0)),0)+IF($C51="Assured",N51*$D51*$C$13*$C$26*$C$27*$C$28,0) -> 53975 | O73: =O51*$D51*$C$13*INDEX(Assumptions!$B$44:$B$46,MATCH($C51,Assumptions!$A$44:$A$46,0))+IF(O$45>=$G51,INDEX(Assumptions!$C$44:$C$46,MATCH($C51,Assumptions!$A$44:$A$46,0)),0)+IF($C51="Assured",O51*$D51*$C$13*$C$26*$C$27*$C$28,0) -> 53975 | ... Y73: =Y51*$D51*$C$13*INDEX(Assumptions!$B$44:$B$46,MATCH($C51,Assumptions!$A$44:$A$46,0))+IF(Y$45>=$G51,INDEX(Assumptions!$C$44:$C$46,MATCH($C51,Assumptions!$A$44:$A$46,0)),0)+IF($C51="Assured",Y51*$D51*$C$13*$C$26*$C$27*$C$28,0) -> 53975
A74: =A52 -> 5 | B74: =B52 -> A | C74: =C52 -> Assured | H74: =H52*$D52*$C$13*INDEX(Assumptions!$B$44:$B$46,MATCH($C52,Assumptions!$A$44:$A$46,0))+IF(H$45>=$G52,INDEX(Assumptions!$C$44:$C$46,MATCH($C52,Assumptions!$A$44:$A$46,0)),0)+IF($C52="Assured",H52*$D52*$C$13*$C$26*$C$27*$C$28,0) -> 0 | I74: =I52*$D52*$C$13*INDEX(Assumptions!$B$44:$B$46,MATCH($C52,Assumptions!$A$44:$A$46,0))+IF(I$45>=$G52,INDEX(Assumptions!$C$44:$C$46,MATCH($C52,Assumptions!$A$44:$A$46,0)),0)+IF($C52="Assured",I52*$D52*$C$13*$C$26*$C$27*$C$28,0) -> 0 | J74: =J52*$D52*$C$13*INDEX(Assumptions!$B$44:$B$46,MATCH($C52,Assumptions!$A$44:$A$46,0))+IF(J$45>=$G52,INDEX(Assumptions!$C$44:$C$46,MATCH($C52,Assumptions!$A$44:$A$46,0)),0)+IF($C52="Assured",J52*$D52*$C$13*$C$26*$C$27*$C$28,0) -> 23317.2 | K74: =K52*$D52*$C$13*INDEX(Assumptions!$B$44:$B$46,MATCH($C52,Assumptions!$A$44:$A$46,0))+IF(K$45>=$G52,INDEX(Assumptions!$C$44:$C$46,MATCH($C52,Assumptions!$A$44:$A$46,0)),0)+IF($C52="Assured",K52*$D52*$C$13*$C$26*$C$27*$C$28,0) -> 46634.4 | L74: =L52*$D52*$C$13*INDEX(Assumptions!$B$44:$B$46,MATCH($C52,Assumptions!$A$44:$A$46,0))+IF(L$45>=$G52,INDEX(Assumptions!$C$44:$C$46,MATCH($C52,Assumptions!$A$44:$A$46,0)),0)+IF($C52="Assured",L52*$D52*$C$13*$C$26*$C$27*$C$28,0) -> 66065.4 | M74: =M52*$D52*$C$13*INDEX(Assumptions!$B$44:$B$46,MATCH($C52,Assumptions!$A$44:$A$46,0))+IF(M$45>=$G52,INDEX(Assumptions!$C$44:$C$46,MATCH($C52,Assumptions!$A$44:$A$46,0)),0)+IF($C52="Assured",M52*$D52*$C$13*$C$26*$C$27*$C$28,0) -> 77724 | N74: =N52*$D52*$C$13*INDEX(Assumptions!$B$44:$B$46,MATCH($C52,Assumptions!$A$44:$A$46,0))+IF(N$45>=$G52,INDEX(Assumptions!$C$44:$C$46,MATCH($C52,Assumptions!$A$44:$A$46,0)),0)+IF($C52="Assured",N52*$D52*$C$13*$C$26*$C$27*$C$28,0) -> 77724 | O74: =O52*$D52*$C$13*INDEX(Assumptions!$B$44:$B$46,MATCH($C52,Assumptions!$A$44:$A$46,0))+IF(O$45>=$G52,INDEX(Assumptions!$C$44:$C$46,MATCH($C52,Assumptions!$A$44:$A$46,0)),0)+IF($C52="Assured",O52*$D52*$C$13*$C$26*$C$27*$C$28,0) -> 77724 | ... Y74: =Y52*$D52*$C$13*INDEX(Assumptions!$B$44:$B$46,MATCH($C52,Assumptions!$A$44:$A$46,0))+IF(Y$45>=$G52,INDEX(Assumptions!$C$44:$C$46,MATCH($C52,Assumptions!$A$44:$A$46,0)),0)+IF($C52="Assured",Y52*$D52*$C$13*$C$26*$C$27*$C$28,0) -> 77724
A75: =A53 -> 6 | B75: =B53 -> A | C75: =C53 -> Assured | H75: =H53*$D53*$C$13*INDEX(Assumptions!$B$44:$B$46,MATCH($C53,Assumptions!$A$44:$A$46,0))+IF(H$45>=$G53,INDEX(Assumptions!$C$44:$C$46,MATCH($C53,Assumptions!$A$44:$A$46,0)),0)+IF($C53="Assured",H53*$D53*$C$13*$C$26*$C$27*$C$28,0) -> 0 | I75: =I53*$D53*$C$13*INDEX(Assumptions!$B$44:$B$46,MATCH($C53,Assumptions!$A$44:$A$46,0))+IF(I$45>=$G53,INDEX(Assumptions!$C$44:$C$46,MATCH($C53,Assumptions!$A$44:$A$46,0)),0)+IF($C53="Assured",I53*$D53*$C$13*$C$26*$C$27*$C$28,0) -> 0 | J75: =J53*$D53*$C$13*INDEX(Assumptions!$B$44:$B$46,MATCH($C53,Assumptions!$A$44:$A$46,0))+IF(J$45>=$G53,INDEX(Assumptions!$C$44:$C$46,MATCH($C53,Assumptions!$A$44:$A$46,0)),0)+IF($C53="Assured",J53*$D53*$C$13*$C$26*$C$27*$C$28,0) -> 23317.2 | K75: =K53*$D53*$C$13*INDEX(Assumptions!$B$44:$B$46,MATCH($C53,Assumptions!$A$44:$A$46,0))+IF(K$45>=$G53,INDEX(Assumptions!$C$44:$C$46,MATCH($C53,Assumptions!$A$44:$A$46,0)),0)+IF($C53="Assured",K53*$D53*$C$13*$C$26*$C$27*$C$28,0) -> 46634.4 | L75: =L53*$D53*$C$13*INDEX(Assumptions!$B$44:$B$46,MATCH($C53,Assumptions!$A$44:$A$46,0))+IF(L$45>=$G53,INDEX(Assumptions!$C$44:$C$46,MATCH($C53,Assumptions!$A$44:$A$46,0)),0)+IF($C53="Assured",L53*$D53*$C$13*$C$26*$C$27*$C$28,0) -> 66065.4 | M75: =M53*$D53*$C$13*INDEX(Assumptions!$B$44:$B$46,MATCH($C53,Assumptions!$A$44:$A$46,0))+IF(M$45>=$G53,INDEX(Assumptions!$C$44:$C$46,MATCH($C53,Assumptions!$A$44:$A$46,0)),0)+IF($C53="Assured",M53*$D53*$C$13*$C$26*$C$27*$C$28,0) -> 77724 | N75: =N53*$D53*$C$13*INDEX(Assumptions!$B$44:$B$46,MATCH($C53,Assumptions!$A$44:$A$46,0))+IF(N$45>=$G53,INDEX(Assumptions!$C$44:$C$46,MATCH($C53,Assumptions!$A$44:$A$46,0)),0)+IF($C53="Assured",N53*$D53*$C$13*$C$26*$C$27*$C$28,0) -> 77724 | O75: =O53*$D53*$C$13*INDEX(Assumptions!$B$44:$B$46,MATCH($C53,Assumptions!$A$44:$A$46,0))+IF(O$45>=$G53,INDEX(Assumptions!$C$44:$C$46,MATCH($C53,Assumptions!$A$44:$A$46,0)),0)+IF($C53="Assured",O53*$D53*$C$13*$C$26*$C$27*$C$28,0) -> 77724 | ... Y75: =Y53*$D53*$C$13*INDEX(Assumptions!$B$44:$B$46,MATCH($C53,Assumptions!$A$44:$A$46,0))+IF(Y$45>=$G53,INDEX(Assumptions!$C$44:$C$46,MATCH($C53,Assumptions!$A$44:$A$46,0)),0)+IF($C53="Assured",Y53*$D53*$C$13*$C$26*$C$27*$C$28,0) -> 77724
A76: =A54 -> 7 | B76: =B54 -> A | C76: =C54 -> Assured | H76: =H54*$D54*$C$13*INDEX(Assumptions!$B$44:$B$46,MATCH($C54,Assumptions!$A$44:$A$46,0))+IF(H$45>=$G54,INDEX(Assumptions!$C$44:$C$46,MATCH($C54,Assumptions!$A$44:$A$46,0)),0)+IF($C54="Assured",H54*$D54*$C$13*$C$26*$C$27*$C$28,0) -> 0 | I76: =I54*$D54*$C$13*INDEX(Assumptions!$B$44:$B$46,MATCH($C54,Assumptions!$A$44:$A$46,0))+IF(I$45>=$G54,INDEX(Assumptions!$C$44:$C$46,MATCH($C54,Assumptions!$A$44:$A$46,0)),0)+IF($C54="Assured",I54*$D54*$C$13*$C$26*$C$27*$C$28,0) -> 0 | J76: =J54*$D54*$C$13*INDEX(Assumptions!$B$44:$B$46,MATCH($C54,Assumptions!$A$44:$A$46,0))+IF(J$45>=$G54,INDEX(Assumptions!$C$44:$C$46,MATCH($C54,Assumptions!$A$44:$A$46,0)),0)+IF($C54="Assured",J54*$D54*$C$13*$C$26*$C$27*$C$28,0) -> 0 | K76: =K54*$D54*$C$13*INDEX(Assumptions!$B$44:$B$46,MATCH($C54,Assumptions!$A$44:$A$46,0))+IF(K$45>=$G54,INDEX(Assumptions!$C$44:$C$46,MATCH($C54,Assumptions!$A$44:$A$46,0)),0)+IF($C54="Assured",K54*$D54*$C$13*$C$26*$C$27*$C$28,0) -> 23317.2 | L76: =L54*$D54*$C$13*INDEX(Assumptions!$B$44:$B$46,MATCH($C54,Assumptions!$A$44:$A$46,0))+IF(L$45>=$G54,INDEX(Assumptions!$C$44:$C$46,MATCH($C54,Assumptions!$A$44:$A$46,0)),0)+IF($C54="Assured",L54*$D54*$C$13*$C$26*$C$27*$C$28,0) -> 46634.4 | M76: =M54*$D54*$C$13*INDEX(Assumptions!$B$44:$B$46,MATCH($C54,Assumptions!$A$44:$A$46,0))+IF(M$45>=$G54,INDEX(Assumptions!$C$44:$C$46,MATCH($C54,Assumptions!$A$44:$A$46,0)),0)+IF($C54="Assured",M54*$D54*$C$13*$C$26*$C$27*$C$28,0) -> 66065.4 | N76: =N54*$D54*$C$13*INDEX(Assumptions!$B$44:$B$46,MATCH($C54,Assumptions!$A$44:$A$46,0))+IF(N$45>=$G54,INDEX(Assumptions!$C$44:$C$46,MATCH($C54,Assumptions!$A$44:$A$46,0)),0)+IF($C54="Assured",N54*$D54*$C$13*$C$26*$C$27*$C$28,0) -> 77724 | O76: =O54*$D54*$C$13*INDEX(Assumptions!$B$44:$B$46,MATCH($C54,Assumptions!$A$44:$A$46,0))+IF(O$45>=$G54,INDEX(Assumptions!$C$44:$C$46,MATCH($C54,Assumptions!$A$44:$A$46,0)),0)+IF($C54="Assured",O54*$D54*$C$13*$C$26*$C$27*$C$28,0) -> 77724 | ... Y76: =Y54*$D54*$C$13*INDEX(Assumptions!$B$44:$B$46,MATCH($C54,Assumptions!$A$44:$A$46,0))+IF(Y$45>=$G54,INDEX(Assumptions!$C$44:$C$46,MATCH($C54,Assumptions!$A$44:$A$46,0)),0)+IF($C54="Assured",Y54*$D54*$C$13*$C$26*$C$27*$C$28,0) -> 77724
A77: =A55 -> 8 | B77: =B55 -> A | C77: =C55 -> Assured | H77: =H55*$D55*$C$13*INDEX(Assumptions!$B$44:$B$46,MATCH($C55,Assumptions!$A$44:$A$46,0))+IF(H$45>=$G55,INDEX(Assumptions!$C$44:$C$46,MATCH($C55,Assumptions!$A$44:$A$46,0)),0)+IF($C55="Assured",H55*$D55*$C$13*$C$26*$C$27*$C$28,0) -> 0 | I77: =I55*$D55*$C$13*INDEX(Assumptions!$B$44:$B$46,MATCH($C55,Assumptions!$A$44:$A$46,0))+IF(I$45>=$G55,INDEX(Assumptions!$C$44:$C$46,MATCH($C55,Assumptions!$A$44:$A$46,0)),0)+IF($C55="Assured",I55*$D55*$C$13*$C$26*$C$27*$C$28,0) -> 0 | J77: =J55*$D55*$C$13*INDEX(Assumptions!$B$44:$B$46,MATCH($C55,Assumptions!$A$44:$A$46,0))+IF(J$45>=$G55,INDEX(Assumptions!$C$44:$C$46,MATCH($C55,Assumptions!$A$44:$A$46,0)),0)+IF($C55="Assured",J55*$D55*$C$13*$C$26*$C$27*$C$28,0) -> 0 | K77: =K55*$D55*$C$13*INDEX(Assumptions!$B$44:$B$46,MATCH($C55,Assumptions!$A$44:$A$46,0))+IF(K$45>=$G55,INDEX(Assumptions!$C$44:$C$46,MATCH($C55,Assumptions!$A$44:$A$46,0)),0)+IF($C55="Assured",K55*$D55*$C$13*$C$26*$C$27*$C$28,0) -> 23317.2 | L77: =L55*$D55*$C$13*INDEX(Assumptions!$B$44:$B$46,MATCH($C55,Assumptions!$A$44:$A$46,0))+IF(L$45>=$G55,INDEX(Assumptions!$C$44:$C$46,MATCH($C55,Assumptions!$A$44:$A$46,0)),0)+IF($C55="Assured",L55*$D55*$C$13*$C$26*$C$27*$C$28,0) -> 46634.4 | M77: =M55*$D55*$C$13*INDEX(Assumptions!$B$44:$B$46,MATCH($C55,Assumptions!$A$44:$A$46,0))+IF(M$45>=$G55,INDEX(Assumptions!$C$44:$C$46,MATCH($C55,Assumptions!$A$44:$A$46,0)),0)+IF($C55="Assured",M55*$D55*$C$13*$C$26*$C$27*$C$28,0) -> 66065.4 | N77: =N55*$D55*$C$13*INDEX(Assumptions!$B$44:$B$46,MATCH($C55,Assumptions!$A$44:$A$46,0))+IF(N$45>=$G55,INDEX(Assumptions!$C$44:$C$46,MATCH($C55,Assumptions!$A$44:$A$46,0)),0)+IF($C55="Assured",N55*$D55*$C$13*$C$26*$C$27*$C$28,0) -> 77724 | O77: =O55*$D55*$C$13*INDEX(Assumptions!$B$44:$B$46,MATCH($C55,Assumptions!$A$44:$A$46,0))+IF(O$45>=$G55,INDEX(Assumptions!$C$44:$C$46,MATCH($C55,Assumptions!$A$44:$A$46,0)),0)+IF($C55="Assured",O55*$D55*$C$13*$C$26*$C$27*$C$28,0) -> 77724 | ... Y77: =Y55*$D55*$C$13*INDEX(Assumptions!$B$44:$B$46,MATCH($C55,Assumptions!$A$44:$A$46,0))+IF(Y$45>=$G55,INDEX(Assumptions!$C$44:$C$46,MATCH($C55,Assumptions!$A$44:$A$46,0)),0)+IF($C55="Assured",Y55*$D55*$C$13*$C$26*$C$27*$C$28,0) -> 77724
...

Sheet Monthly_Downside
A1: Monthly engine — Downside scenario (M1–M18)
A2: All values flow from the Assumptions tab. Green = linked input.
A4: ID | B4: Parameter | C4: Value
A5: A1 | B5: =Assumptions!B5 -> Capture of Exhibit 2 mature volume | C5: =Assumptions!D5 -> 0.65
A6: A2 | B6: =Assumptions!B6 -> Ramp: share of mature volume, live month 1 | C6: =Assumptions!D6 -> 0.3
A7: A3 | B7: =Assumptions!B7 -> Ramp: live month 2 | C7: =Assumptions!D7 -> 0.6
A8: A4 | B8: =Assumptions!B8 -> Ramp: live month 3 | C8: =Assumptions!D8 -> 0.85
A9: A5 | B9: =Assumptions!B9 -> Ramp: live month 4+ | C9: =Assumptions!D9 -> 1
A10: A6 | B10: =Assumptions!B10 -> Pilot host bookings/month today | C10: =Assumptions!D10 -> 17.5
A11: A7 | B11: =Assumptions!B11 -> Pilot host bookings/month after Assured conversion | C11: =Assumptions!D11 -> 20
A12: A8 | B12: =Assumptions!B12 -> Months for pilot hosts to reach target | C12: =Assumptions!D12 -> 3
A13: A9 | B13: =Assumptions!B13 -> Average booking value multiplier | C13: =Assumptions!D13 -> 0.9
A14: A10 | B14: =Assumptions!B14 -> Bookings lost to cancellation (beyond tier on-time) | C14: =Assumptions!D14 -> 0.05
A15: A11 | B15: =Assumptions!B15 -> Onboarding delay for new hosts | C15: =Assumptions!D15 -> 2
A16: A12 | B16: =Assumptions!B16 -> Fixed cost multiplier | C16: =Assumptions!D16 -> 1.15
... A40: A36 | B40: =Assumptions!B40 -> City-4 (Cluster B) cost removed from month | C40: =Assumptions!D40 -> 99
A45: Month → | H45: 1 | I45: 2 | J45: 3 | K45: 4 | L45: 5 | M45: 6 | N45: 7 | O45: 8 | P45: 9 | Q45: 10 | R45: 11 | S45: 12 | T45: 13 | U45: 14 | V45: 15 | W45: 16 | X45: 17 | Y45: 18
A47: Bookings per host | B47: Cluster | C47: Tier | D47: Booking value ₹ | E47: Mature/month | F47: Pilot? | G47: Live from month
A48: =Assumptions!A57 -> 1 | B48: =Assumptions!B57 -> Pilot | C48: =Assumptions!C57 -> Assured | D48: =Assumptions!D57 -> 8500 | E48: =Assumptions!E57 -> 20 | F48: =Assumptions!G57 -> 1 | G48: =Assumptions!F57+IF(F48=1,0,$C$15) -> 1 | H48: =IF(H$45<$G48,0,IF($F48=1,$C$10+($C$11-$C$10)*MIN(H$45-$G48,$C$12)/$C$12,$E48*$C$5*INDEX($C$6:$C$9,MIN(H$45-$G48,3)+1)))*(1-$C$14)*IF(AND($C48="Verified",$C$39=1),0,1) -> 16.625 | I48: =IF(I$45<$G48,0,IF($F48=1,$C$10+($C$11-$C$10)*MIN(I$45-$G48,$C$12)/$C$12,$E48*$C$5*INDEX($C$6:$C$9,MIN(I$45-$G48,3)+1)))*(1-$C$14)*IF(AND($C48="Verified",$C$39=1),0,1) -> 17.416667 | J48: =IF(J$45<$G48,0,IF($F48=1,$C$10+($C$11-$C$10)*MIN(J$45-$G48,$C$12)/$C$12,$E48*$C$5*INDEX($C$6:$C$9,MIN(J$45-$G48,3)+1)))*(1-$C$14)*IF(AND($C48="Verified",$C$39=1),0,1) -> 18.208333 | K48: =IF(K$45<$G48,0,IF($F48=1,$C$10+($C$11-$C$10)*MIN(K$45-$G48,$C$12)/$C$12,$E48*$C$5*INDEX($C$6:$C$9,MIN(K$45-$G48,3)+1)))*(1-$C$14)*IF(AND($C48="Verified",$C$39=1),0,1) -> 19 | L48: =IF(L$45<$G48,0,IF($F48=1,$C$10+($C$11-$C$10)*MIN(L$45-$G48,$C$12)/$C$12,$E48*$C$5*INDEX($C$6:$C$9,MIN(L$45-$G48,3)+1)))*(1-$C$14)*IF(AND($C48="Verified",$C$39=1),0,1) -> 19 | M48: =IF(M$45<$G48,0,IF($F48=1,$C$10+($C$11-$C$10)*MIN(M$45-$G48,$C$12)/$C$12,$E48*$C$5*INDEX($C$6:$C$9,MIN(M$45-$G48,3)+1)))*(1-$C$14)*IF(AND($C48="Verified",$C$39=1),0,1) -> 19 | N48: =IF(N$45<$G48,0,IF($F48=1,$C$10+($C$11-$C$10)*MIN(N$45-$G48,$C$12)/$C$12,$E48*$C$5*INDEX($C$6:$C$9,MIN(N$45-$G48,3)+1)))*(1-$C$14)*IF(AND($C48="Verified",$C$39=1),0,1) -> 19 | O48: =IF(O$45<$G48,0,IF($F48=1,$C$10+($C$11-$C$10)*MIN(O$45-$G48,$C$12)/$C$12,$E48*$C$5*INDEX($C$6:$C$9,MIN(O$45-$G48,3)+1)))*(1-$C$14)*IF(AND($C48="Verified",$C$39=1),0,1) -> 19 | ... Y48: =IF(Y$45<$G48,0,IF($F48=1,$C$10+($C$11-$C$10)*MIN(Y$45-$G48,$C$12)/$C$12,$E48*$C$5*INDEX($C$6:$C$9,MIN(Y$45-$G48,3)+1)))*(1-$C$14)*IF(AND($C48="Verified",$C$39=1),0,1) -> 19
A49: =Assumptions!A58 -> 2 | B49: =Assumptions!B58 -> Pilot | C49: =Assumptions!C58 -> Assured | D49: =Assumptions!D58 -> 8500 | E49: =Assumptions!E58 -> 20 | F49: =Assumptions!G58 -> 1 | G49: =Assumptions!F58+IF(F49=1,0,$C$15) -> 1 | H49: =IF(H$45<$G49,0,IF($F49=1,$C$10+($C$11-$C$10)*MIN(H$45-$G49,$C$12)/$C$12,$E49*$C$5*INDEX($C$6:$C$9,MIN(H$45-$G49,3)+1)))*(1-$C$14)*IF(AND($C49="Verified",$C$39=1),0,1) -> 16.625 | I49: =IF(I$45<$G49,0,IF($F49=1,$C$10+($C$11-$C$10)*MIN(I$45-$G49,$C$12)/$C$12,$E49*$C$5*INDEX($C$6:$C$9,MIN(I$45-$G49,3)+1)))*(1-$C$14)*IF(AND($C49="Verified",$C$39=1),0,1) -> 17.416667 | J49: =IF(J$45<$G49,0,IF($F49=1,$C$10+($C$11-$C$10)*MIN(J$45-$G49,$C$12)/$C$12,$E49*$C$5*INDEX($C$6:$C$9,MIN(J$45-$G49,3)+1)))*(1-$C$14)*IF(AND($C49="Verified",$C$39=1),0,1) -> 18.208333 | K49: =IF(K$45<$G49,0,IF($F49=1,$C$10+($C$11-$C$10)*MIN(K$45-$G49,$C$12)/$C$12,$E49*$C$5*INDEX($C$6:$C$9,MIN(K$45-$G49,3)+1)))*(1-$C$14)*IF(AND($C49="Verified",$C$39=1),0,1) -> 19 | L49: =IF(L$45<$G49,0,IF($F49=1,$C$10+($C$11-$C$10)*MIN(L$45-$G49,$C$12)/$C$12,$E49*$C$5*INDEX($C$6:$C$9,MIN(L$45-$G49,3)+1)))*(1-$C$14)*IF(AND($C49="Verified",$C$39=1),0,1) -> 19 | M49: =IF(M$45<$G49,0,IF($F49=1,$C$10+($C$11-$C$10)*MIN(M$45-$G49,$C$12)/$C$12,$E49*$C$5*INDEX($C$6:$C$9,MIN(M$45-$G49,3)+1)))*(1-$C$14)*IF(AND($C49="Verified",$C$39=1),0,1) -> 19 | N49: =IF(N$45<$G49,0,IF($F49=1,$C$10+($C$11-$C$10)*MIN(N$45-$G49,$C$12)/$C$12,$E49*$C$5*INDEX($C$6:$C$9,MIN(N$45-$G49,3)+1)))*(1-$C$14)*IF(AND($C49="Verified",$C$39=1),0,1) -> 19 | O49: =IF(O$45<$G49,0,IF($F49=1,$C$10+($C$11-$C$10)*MIN(O$45-$G49,$C$12)/$C$12,$E49*$C$5*INDEX($C$6:$C$9,MIN(O$45-$G49,3)+1)))*(1-$C$14)*IF(AND($C49="Verified",$C$39=1),0,1) -> 19 | ... Y49: =IF(Y$45<$G49,0,IF($F49=1,$C$10+($C$11-$C$10)*MIN(Y$45-$G49,$C$12)/$C$12,$E49*$C$5*INDEX($C$6:$C$9,MIN(Y$45-$G49,3)+1)))*(1-$C$14)*IF(AND($C49="Verified",$C$39=1),0,1) -> 19
